File: src/bin/Termo/Example Data/02.txt
#FILE:VA_130319_Cu_02_Ar.ngb-ss1
#FORMAT:NETZSCH5
#IDENTITY:VA_130319_Cu_02_Ar
#DECIMAL:POINT
#SEPARATOR:SEMICOLON
#MTYPE:DSC
#INSTRUMENT:NETZSCH STA 449F1
#PROJECT:oxide hydroxide
#DATE/TIME:19.03.2013 11:34:23
#CORR. FILE:
#LABORATORY:Нанотех
#OPERATOR:Compositers
#REMARK:
#SAMPLE:VA_130319_Cu_02_Ar
#SAMPLE MASS /mg:7.81
#MATERIAL:MxOy.kH2O
#REFERENCE:
#REFERENCE MASS /mg:0
#TYPE OF CRUCIBLE:DSC/TG pan Pt-Rh
#SAMPLE CRUCIBLE MASS /mg:183.71
#REFERENCE CRUCIBLE MASS /mg:185
#CORR. CODE:000
#EXO:+1
#RANGE:20/2.0(K/min)/350
#SEGMENT:S1/1

##Temp./°C;Time/min;DSC/(uV/mg);Mass/%;Gas Flow(protective)/(ml/min);Sensit./(uV/mW)
23.9404	     0.00000      0.25692   100.0000   20.00000 1.04891
23.9407	     0.33000      0.25682   99.99452   20.00000 1.04891
23.9461	     0.66000      0.25623   99.99427   20.00000 1.04891
23.9709	     0.99000      0.25643   99.98712   20.00000 1.04891
24.0271	     1.32000      0.25653   99.97543   20.00000 1.04891
24.1237	     1.65000      0.25653   99.98352   20.00000 1.04891
24.2685	     1.98000      0.25623   99.99575   20.00000 1.04891
24.4674	     2.31000      0.25467   100.0187   20.00000 1.04890
24.7149	     2.64000      0.25262   100.0235   20.00000 1.04887
24.9998	     2.97000      0.24881   100.0061   20.00000 1.04881
25.3163	     3.30000      0.24402   99.99407   20.00000 1.04873
25.6664	     3.63000      0.23973   99.9874   20.00000 1.04862
26.0473	     3.96000      0.23416   99.99915   20.00000 1.04848
26.4549	     4.29000      0.23015   99.99648   20.00000 1.04833
26.8837	     4.62000      0.22605   99.98917   20.00000 1.04815
27.3308	     4.95000      0.22283   100.0012   20.00000 1.04796
27.7953	     5.28000      0.22019   100.0015   20.00000 1.04775
28.2757	     5.61000      0.21745   100.0012   20.00000 1.04752
28.7716	     5.94000      0.21560   100.0028   20.00000 1.04728
29.2814	     6.27000      0.21325   100.0066   20.00000 1.04703
29.8023	     6.60000      0.21013   99.99882   20.00000 1.04677
30.3329	     6.93000      0.20886   99.99983   20.00000 1.04651
30.8704	     7.26000      0.20602   99.99853   20.00000 1.04623
31.4152	     7.59000      0.20348   100.0038   20.00000 1.04595
31.9725	     7.92000      0.20133   99.9958   20.00000 1.04566
32.5361	     8.25000      0.20006   100.0008   20.00000 1.04537
33.108	     8.58000      0.19909   100.0017   20.00000 1.04507
33.6839	     8.91000      0.19743   100.0031   20.00000 1.04476
34.2649	     9.24000      0.19577   99.99647   20.00000 1.04445
34.8501	     9.57000      0.19362   100.0047   20.00000 1.04414
35.4364	     9.90000      0.19274   100.0004   20.00000 1.04382
36.0282	    10.23000      0.19147   99.99903   20.00000 1.04350
36.6245	    10.56000      0.19020   99.99999   20.00000 1.04318
37.2239	    10.89000      0.18873   100.0026   20.00000 1.04285
37.8251	    11.22000      0.18688   99.99646   20.00000 1.04253
38.4299	    11.55000      0.18561   99.99243   20.00000 1.04220
39.0388	    11.88000      0.18385   99.98826   20.00000 1.04187
39.6507	    12.21000      0.18199   99.97695   20.00000 1.04153
40.2625	    12.54000      0.18141   99.93528   20.00000 1.04120
40.8757	    12.87000      0.17838   99.89949   20.00000 1.04086
41.4899	    13.20000      0.17691   99.8487   20.00000 1.04053
42.1042	    13.53000      0.17554   99.79988   20.00000 1.04018
42.7156	    13.86000      0.17310   99.73594   20.00000 1.03984
43.3238	    14.19000      0.17027   99.66959   20.00000 1.03950
43.9276	    14.52000      0.16665   99.56372   20.00000 1.03916
44.5284	    14.85000      0.16021   99.46223   20.00000 1.03882
45.1298	    15.18000      0.12494   99.33513   20.00000 1.03848
45.7335	    15.51000  4.9625e-002   99.20655   20.00000 1.03814
46.3389	    15.84000 -1.9342e-002   99.06446   20.00000 1.03780
46.9448	    16.17000 -6.7502e-002   98.91782   20.00000 1.03747
47.5482	    16.50000     -0.10247   98.7378   20.00000 1.03713
48.152	    16.83000     -0.13217   98.51451   20.00000 1.03680
48.7576	    17.16000     -0.16060   98.27837   20.00000 1.03646
49.3651	    17.49000     -0.18961   98.0248   20.00000 1.03612
49.9737	    17.82000     -0.21735   97.75931   20.00000 1.03579
50.5802	    18.15000     -0.24510   97.44481   20.00000 1.03545
51.1834	    18.48000     -0.27392   97.13817   20.00000 1.03511
51.7871	    18.81000     -0.30312   96.79866   20.00000 1.03478
52.3928	    19.14000     -0.32960   96.45281   20.00000 1.03444
53.0022	    19.47000     -0.35754   96.0849   20.00000 1.03410
53.613	    19.80000     -0.38528   95.70008   20.00000 1.03376
54.2213	    20.13000     -0.41390   95.29186   20.00000 1.03343
54.8309	    20.46000     -0.44174   94.86638   20.00000 1.03309
55.4447	    20.79000     -0.46900   94.41896   20.00000 1.03275
56.0601	    21.12000     -0.49684   93.96247   20.00000 1.03241
56.6758	    21.45000     -0.52497   93.47441   20.00000 1.03207
57.2895	    21.78000     -0.55223   92.97826   20.00000 1.03173
57.9046	    22.11000     -0.57870   92.4604   20.00000 1.03139
58.5207	    22.44000     -0.60605   91.92997   20.00000 1.03104
59.1368	    22.77000     -0.63038   91.36609   20.00000 1.03070
59.754	    23.10000     -0.65617   90.80198   20.00000 1.03036
60.3734	    23.43000     -0.68010   90.24297   20.00000 1.03002
60.9967	    23.76000     -0.70169   89.6367   20.00000 1.02967
61.6228	    24.09000     -0.72025   89.0233   20.00000 1.02933
62.2522	    24.42000     -0.73754   88.4366   20.00000 1.02899
62.8859	    24.75000     -0.75004   87.8382   20.00000 1.02864
63.5306	    25.08000     -0.75630   87.2776   20.00000 1.02829
64.1887	    25.41000     -0.75317   86.7638   20.00000 1.02794
64.8666	    25.74000     -0.73481   86.367   20.00000 1.02759
65.5598	    26.07000     -0.69427   86.0566   20.00000 1.02724
66.2618	    26.40000     -0.61553   85.8058   20.00000 1.02688
66.9582	    26.73000     -0.47808   85.6465   20.00000 1.02651
67.6449	    27.06000     -0.24500   85.594   20.00000 1.02613
68.3224	    27.39000 -3.4188e-003   85.5692   20.00000 1.02575
68.9941	    27.72000  9.8860e-002   85.538   20.00000 1.02536
69.6608	    28.05000      0.13549   85.5195   20.00000 1.02497
70.3237	    28.38000      0.14819   85.4925   20.00000 1.02459
70.9823	    28.71000      0.15532   85.4822   20.00000 1.02421
71.6394	    29.04000      0.16031   85.468   20.00000 1.02383
72.2951	    29.37000      0.16314   85.4511   20.00000 1.02346
72.9476	    29.70000      0.16451   85.4417   20.00000 1.02309
73.5986	    30.03000      0.16480   85.4277   20.00000 1.02272
74.2474	    30.36000      0.16490   85.4104   20.00000 1.02236
74.898	    30.69000      0.16587   85.3983   20.00000 1.02199
75.5467	    31.02000      0.16587   85.3848   20.00000 1.02163
76.1881	    31.35000      0.16548   85.3633   20.00000 1.02126
76.8284	    31.68000      0.16490   85.355   20.00000 1.02090
77.4666	    32.01000      0.16412   85.3508   20.00000 1.02054
78.1086	    32.34000      0.16314   85.3307   20.00000 1.02018
78.7486	    32.67000      0.16187   85.3186   20.00000 1.01982
79.3889	    33.00000      0.15991   85.3092   20.00000 1.01946
80.0318	    33.33000      0.15825   85.2929   20.00000 1.01911
80.6784	    33.66000      0.15747   85.2716   20.00000 1.01875
81.3243	    33.99000      0.15591   85.2564   20.00000 1.01839
81.9655	    34.32000      0.15425   85.2344   20.00000 1.01804
82.6011	    34.65000      0.15249   85.2183   20.00000 1.01768
83.2368	    34.98000      0.15005   85.1972   20.00000 1.01732
83.8757	    35.31000      0.14839   85.1769   20.00000 1.01696
84.516	    35.64000      0.14653   85.1602   20.00000 1.01660
85.1563	    35.97000      0.14477   85.1407   20.00000 1.01624
85.7978	    36.30000      0.14360   85.1172   20.00000 1.01589
86.4411	    36.63000      0.14087   85.0975   20.00000 1.01553
87.0857	    36.96000      0.13823   85.0815   20.00000 1.01518
87.7274	    37.29000      0.13520   85.0494   20.00000 1.01482
88.3688	    37.62000      0.13403   85.0137   20.00000 1.01446
89.0061	    37.95000      0.13110   84.9956   20.00000 1.01410
89.6452	    38.28000      0.12856   84.9585   20.00000 1.01374
90.2865	    38.61000      0.12484   84.9301   20.00000 1.01339
90.9349	    38.94000      0.12260   84.9053   20.00000 1.01303
91.5816	    39.27000      0.12016   84.8629   20.00000 1.01267
92.2238	    39.60000      0.11693   84.8228   20.00000 1.01232
92.8652	    39.93000      0.11312   84.7678   20.00000 1.01196
93.5049	    40.26000      0.10970   84.638   20.00000 1.01160
94.1286	    40.59000      0.10511   84.2901   20.00000 1.01124
94.6997	    40.92000      0.10072   83.4751   20.00000 1.01088
95.2105	    41.25000  9.2999e-002   82.1841   20.00000 1.01052
95.6858	    41.58000  7.1605e-002   80.8027   20.00000 1.01017
96.1666	    41.91000 -8.6258e-002   79.4128   20.00000 1.00982
96.6822	    42.24000     -0.67052   78.0131   20.00000 1.00950
97.2346	    42.57000     -1.68189   76.6839   20.00000 1.00922
97.823	    42.90000     -2.12812   75.5251   20.00000 1.00895
98.4444	    43.23000     -2.27153   74.5568   20.00000 1.00868
99.0957	    43.56000     -2.26684   73.7136   20.00000 1.00840
99.7686	    43.89000     -2.14854   73.0151   20.00000 1.00809
100.458	    44.22000     -1.94809   72.4622   20.00000 1.00776
101.161	    44.55000     -1.70885   72.0662   20.00000 1.00741
101.877	    44.88000     -1.46424   71.8143   20.00000 1.00705
102.597	    45.21000     -1.21709   71.665   20.00000 1.00668
103.32	    45.54000     -0.96662   71.5704   20.00000 1.00629
104.044	    45.87000     -0.71331   71.503   20.00000 1.00590
104.765	    46.20000     -0.45728   71.4473   20.00000 1.00550
105.477	    46.53000     -0.22585   71.4148   20.00000 1.00510
106.176	    46.86000 -6.6818e-002   71.3871   20.00000 1.00470
106.869	    47.19000  1.9538e-002   71.3769   20.00000 1.00430
107.555	    47.52000  6.6330e-002   71.3505   20.00000 1.00390
108.239	    47.85000      0.10033   71.3394   20.00000 1.00350
108.918	    48.18000      0.12690   71.3314   20.00000 1.00311
109.594	    48.51000      0.14399   71.3215   20.00000 1.00273
110.268	    48.84000      0.15249   71.3083   20.00000 1.00234
110.937	    49.17000      0.15757   71.3   20.00000 1.00196
111.603	    49.50000      0.16050   71.2884   20.00000 1.00159
112.266	    49.83000      0.16382   71.2852   20.00000 1.00121
112.927	    50.16000      0.16451   71.2733   20.00000 1.00083
113.584	    50.49000      0.16558   71.2635   20.00000 1.00046
114.24	    50.82000      0.16685   71.2661   20.00000 1.00009
114.895	    51.15000      0.16724   71.2507   20.00000 0.99972
115.549	    51.48000      0.16802   71.2484   20.00000 0.99936
116.201	    51.81000      0.16871   71.2456   20.00000 0.99899
116.853	    52.14000      0.16871   71.2318   20.00000 0.99863
117.502	    52.47000      0.16959   71.2261   20.00000 0.99826
118.15	    52.80000      0.16880   71.2214   20.00000 0.99790
118.797	    53.13000      0.16939   71.2155   20.00000 0.99754
119.45	    53.46000      0.16978   71.2064   20.00000 0.99718
120.103	    53.79000      0.16871   71.2053   20.00000 0.99682
120.754	    54.12000      0.16959   71.2139   20.00000 0.99646
121.407	    54.45000      0.16929   71.2036   20.00000 0.99610
122.061	    54.78000      0.16900   71.1904   20.00000 0.99573
122.717	    55.11000      0.16822   71.189   20.00000 0.99537
123.373	    55.44000      0.16832   71.1767   20.00000 0.99501
124.028	    55.77000      0.16812   71.1736   20.00000 0.99465
124.683	    56.10000      0.16851   71.18   20.00000 0.99429
125.334	    56.43000      0.16802   71.1636   20.00000 0.99392
125.982	    56.76000      0.16832   71.159   20.00000 0.99356
126.631	    57.09000      0.16832   71.1587   20.00000 0.99319
127.28	    57.42000      0.16910   71.1518   20.00000 0.99283
127.929	    57.75000      0.16851   71.1475   20.00000 0.99247
128.58	    58.08000      0.16792   71.1493   20.00000 0.99211
129.232	    58.41000      0.16753   71.1402   20.00000 0.99175
129.886	    58.74000      0.16773   71.1344   20.00000 0.99139
130.539	    59.07000      0.16802   71.1231   20.00000 0.99103
131.191	    59.40000      0.16753   71.1284   20.00000 0.99067
131.841	    59.73000      0.16724   71.119   20.00000 0.99031
132.491	    60.06000      0.16714   71.113   20.00000 0.98995
133.141	    60.39000      0.16734   71.1049   20.00000 0.98959
133.791	    60.72000      0.16695   71.1111   20.00000 0.98923
134.44	    61.05000      0.16714   71.0956   20.00000 0.98887
135.091	    61.38000      0.16724   71.0961   20.00000 0.98851
135.743	    61.71000      0.16675   71.0933   20.00000 0.98815
136.395	    62.04000      0.16685   71.0866   20.00000 0.98779
137.046	    62.37000      0.16646   71.0801   20.00000 0.98743
137.694	    62.70000      0.16665   71.0753   20.00000 0.98707
138.338	    63.03000      0.16626   71.0771   20.00000 0.98671
138.989	    63.36000      0.16597   71.0713   20.00000 0.98635
139.643	    63.69000      0.16656   71.0713   20.00000 0.98599
140.301	    64.02000      0.16626   71.0628   20.00000 0.98563
140.954	    64.35000      0.16558   71.0593   20.00000 0.98527
141.606	    64.68000      0.16548   71.056   20.00000 0.98491
142.258	    65.01000      0.16558   71.0532   20.00000 0.98455
142.909	    65.34000      0.16509   71.0402   20.00000 0.98419
143.563	    65.67000      0.16499   71.0358   20.00000 0.98383
144.214	    66.00000      0.16451   71.0298   20.00000 0.98347
144.867	    66.33000      0.16509   71.0319   20.00000 0.98311
145.517	    66.66000      0.16451   71.0216   20.00000 0.98275
146.166	    66.99000      0.16431   71.0163   20.00000 0.98239
146.816	    67.32000      0.16519   71.0092   20.00000 0.98203
147.467	    67.65000      0.16470   71.0108   20.00000 0.98167
148.12	    67.98000      0.16499   70.9947   20.00000 0.98131
148.769	    68.31000      0.16441   70.9912   20.00000 0.98095
149.419	    68.64000      0.16412   70.9892   20.00000 0.98060
150.069	    68.97000      0.16431   70.9844   20.00000 0.98024
150.725	    69.30000      0.16421   70.9848   20.00000 0.97988
151.383	    69.63000      0.16353   70.9792   20.00000 0.97952
152.04	    69.96000      0.16431   70.9728   20.00000 0.97916
152.694	    70.29000      0.16343   70.9673   20.00000 0.97880
153.349	    70.62000      0.16265   70.9624   20.00000 0.97844
154.005	    70.95000      0.16333   70.9577   20.00000 0.97808
154.66	    71.28000      0.16304   70.9527   20.00000 0.97772
155.316	    71.61000      0.16294   70.954   20.00000 0.97736
155.971	    71.94000      0.16343   70.9511   20.00000 0.97700
156.626	    72.27000      0.16275   70.9472   20.00000 0.97664
157.279	    72.60000      0.16304   70.9346   20.00000 0.97628
157.932	    72.93000      0.16245   70.9293   20.00000 0.97592
158.587	    73.26000      0.16255   70.9224   20.00000 0.97556
159.243	    73.59000      0.16197   70.9198   20.00000 0.97520
159.897	    73.92000      0.16265   70.9125   20.00000 0.97484
160.549	    74.25000      0.16216   70.9021   20.00000 0.97448
161.206	    74.58000      0.16177   70.9019   20.00000 0.97412
161.863	    74.91000      0.16128   70.8971   20.00000 0.97376
162.523	    75.24000      0.16197   70.8954   20.00000 0.97340
163.179	    75.57000      0.16206   70.8837   20.00000 0.97305
163.834	    75.90000      0.16138   70.8772   20.00000 0.97269
164.489	    76.23000      0.16060   70.8704   20.00000 0.97233
165.146	    76.56000      0.16050   70.8686   20.00000 0.97196
165.803	    76.89000      0.16031   70.8651   20.00000 0.97160
166.459	    77.22000      0.15991   70.8597   20.00000 0.97125
167.116	    77.55000      0.15933   70.8564   20.00000 0.97089
167.772	    77.88000      0.15962   70.8505   20.00000 0.97053
168.426	    78.21000      0.15913   70.8395   20.00000 0.97017
169.081	    78.54000      0.15952   70.8303   20.00000 0.96981
169.736	    78.87000      0.16001   70.8148   20.00000 0.96945
170.393	    79.20000      0.15884   70.8172   20.00000 0.96909
171.045	    79.53000      0.15884   70.8085   20.00000 0.96873
171.699	    79.86000      0.15777   70.8018   20.00000 0.96838
172.353	    80.19000      0.15825   70.8018   20.00000 0.96802
173.008	    80.52000      0.15747   70.7894   20.00000 0.96766
173.663	    80.85000      0.15718   70.7843   20.00000 0.96730
174.314	    81.18000      0.15698   70.768   20.00000 0.96695
174.967	    81.51000      0.15708   70.7627   20.00000 0.96659
175.618	    81.84000      0.15640   70.7402   20.00000 0.96623
176.27	    82.17000      0.15620   70.7234   20.00000 0.96587
176.923	    82.50000      0.15571   70.7062   20.00000 0.96552
177.576	    82.83000      0.15562   70.6848   20.00000 0.96516
178.228	    83.16000      0.15523   70.66   20.00000 0.96481
178.881	    83.49000      0.15298   70.6341   20.00000 0.96445
179.536	    83.82000      0.15093   70.6013   20.00000 0.96410
180.19	    84.15000      0.14809   70.5571   20.00000 0.96374
180.845	    84.48000      0.14516   70.5084   20.00000 0.96339
181.498	    84.81000      0.14057   70.4716   20.00000 0.96303
182.154	    85.14000      0.13422   70.4215   20.00000 0.96268
182.807	    85.47000      0.12729   70.368   20.00000 0.96232
183.461	    85.80000      0.11928   70.3079   20.00000 0.96196
184.112	    86.13000      0.11009   70.2593   20.00000 0.96161
184.761	    86.46000      0.10072   70.1906   20.00000 0.96125
185.412	    86.79000  9.1436e-002   70.124   20.00000 0.96090
186.068	    87.12000  8.1765e-002   70.0461   20.00000 0.96054
186.726	    87.45000  7.1312e-002   69.9714   20.00000 0.96019
187.381	    87.78000  6.2422e-002   69.898   20.00000 0.95984
188.031	    88.11000  5.2947e-002   69.8138   20.00000 0.95948
188.682	    88.44000  4.3276e-002   69.7336   20.00000 0.95913
189.334	    88.77000  3.5558e-002   69.65   20.00000 0.95877
189.988	    89.10000  2.7059e-002   69.5627   20.00000 0.95842
190.643	    89.43000  1.8463e-002   69.4759   20.00000 0.95806
191.297	    89.76000  1.1332e-002   69.3778   20.00000 0.95771
191.952	    90.09000  4.2007e-003   69.2712   20.00000 0.95736
192.605	    90.42000 -3.0283e-003   69.167   20.00000 0.95700
193.256	    90.75000 -1.0160e-002   69.0589   20.00000 0.95665
193.907	    91.08000 -1.7193e-002   68.9575   20.00000 0.95630
194.557	    91.41000 -2.3933e-002   68.8464   20.00000 0.95594
195.213	    91.74000 -3.0088e-002   68.7338   20.00000 0.95559
195.868	    92.07000 -3.6633e-002   68.6211   20.00000 0.95524
196.526	    92.40000 -4.2689e-002   68.5044   20.00000 0.95489
197.182	    92.73000 -4.8453e-002   68.3857   20.00000 0.95453
197.838	    93.06000 -5.3044e-002   68.2675   20.00000 0.95418
198.496	    93.39000 -5.8613e-002   68.1426   20.00000 0.95383
199.152	    93.72000 -6.3888e-002   68.0122   20.00000 0.95347
199.809	    94.05000 -6.8381e-002   67.8881   20.00000 0.95312
200.466	    94.38000 -7.2679e-002   67.758   20.00000 0.95276
201.126	    94.71000 -7.6489e-002   67.6404   20.00000 0.95241
201.786	    95.04000 -8.0006e-002   67.4962   20.00000 0.95206
202.444	    95.37000 -8.3718e-002   67.385   20.00000 0.95170
203.1	    95.70000 -8.6551e-002   67.2567   20.00000 0.95135
203.757	    96.03000 -9.0068e-002   67.1234   20.00000 0.95099
204.414	    96.36000 -9.1142e-002   67.0032   20.00000 0.95064
205.069	    96.69000 -9.2999e-002   66.8635   20.00000 0.95029
205.725	    97.02000 -9.4464e-002   66.7376   20.00000 0.94993
206.381	    97.35000 -9.5538e-002   66.6248   20.00000 0.94958
207.038	    97.68000 -9.6320e-002   66.5075   20.00000 0.94923
207.693	    98.01000 -9.5050e-002   66.3816   20.00000 0.94888
208.347	    98.34000 -9.4366e-002   66.2611   20.00000 0.94852
209.005	    98.67000 -9.3096e-002   66.1398   20.00000 0.94817
209.663	    99.00000 -9.2119e-002   66.0354   20.00000 0.94782
210.323	    99.33000 -9.0361e-002   65.9187   20.00000 0.94747
210.98	    99.66000 -8.8700e-002   65.8226   20.00000 0.94712
211.637	    99.99000 -8.5867e-002   65.7066   20.00000 0.94677
212.294	   100.32000 -8.3034e-002   65.5904   20.00000 0.94641
212.953	   100.65000 -7.9615e-002   65.507   20.00000 0.94606
213.61	   100.98000 -7.6196e-002   65.4088   20.00000 0.94571
214.269	   101.31000 -7.2777e-002   65.3124   20.00000 0.94536
214.93	   101.64000 -6.8870e-002   65.2298   20.00000 0.94501
215.591	   101.97000 -6.4865e-002   65.1414   20.00000 0.94465
216.254	   102.30000 -6.1153e-002   65.05   20.00000 0.94430
216.913	   102.63000 -5.6170e-002   64.9882   20.00000 0.94395
217.571	   102.96000 -5.1579e-002   64.8938   20.00000 0.94360
218.228	   103.29000 -4.7672e-002   64.8264   20.00000 0.94324
218.886	   103.62000 -4.2885e-002   64.7599   20.00000 0.94289
219.543	   103.95000 -3.7707e-002   64.69   20.00000 0.94254
220.201	   104.28000 -3.2335e-002   64.6301   20.00000 0.94219
220.858	   104.61000 -2.6180e-002   64.5569   20.00000 0.94184
221.517	   104.94000 -2.0905e-002   64.5034   20.00000 0.94149
222.177	   105.27000 -1.4458e-002   64.4486   20.00000 0.94114
222.838	   105.60000 -8.7919e-003   64.4009   20.00000 0.94079
223.497	   105.93000 -3.4191e-003   64.3425   20.00000 0.94044
224.152	   106.26000  2.6375e-003   64.2925   20.00000 0.94009
224.805	   106.59000  9.4757e-003   64.2451   20.00000 0.93974
225.46	   106.92000  1.4653e-002   64.2113   20.00000 0.93939
226.119	   107.25000  2.1101e-002   64.1547   20.00000 0.93904
226.782	   107.58000  2.8134e-002   64.1268   20.00000 0.93869
227.448	   107.91000  3.5167e-002   64.0856   20.00000 0.93834
228.112	   108.24000  4.1517e-002   64.0521   20.00000 0.93800
228.775	   108.57000  4.7378e-002   64.0301   20.00000 0.93765
229.434	   108.90000  5.4314e-002   63.9893   20.00000 0.93730
230.092	   109.23000  6.0762e-002   63.9622   20.00000 0.93694
230.75	   109.56000  6.7600e-002   63.9449   20.00000 0.93659
231.409	   109.89000  7.3363e-002   63.9111   20.00000 0.93624
232.066	   110.22000  8.0494e-002   63.9021   20.00000 0.93589
232.727	   110.55000  8.6844e-002   63.8763   20.00000 0.93555
233.388	   110.88000  9.2217e-002   63.8562   20.00000 0.93520
234.048	   111.21000  9.8567e-002   63.8372   20.00000 0.93485
234.706	   111.54000      0.10384   63.8208   20.00000 0.93450
235.364	   111.87000      0.10980   63.8073   20.00000 0.93416
236.022	   112.20000      0.11566   63.7898   20.00000 0.93381
236.679	   112.53000      0.12064   63.7851   20.00000 0.93346
237.335	   112.86000      0.12533   63.7825   20.00000 0.93311
237.993	   113.19000      0.13051   63.7757   20.00000 0.93277
238.652	   113.52000      0.13481   63.7619   20.00000 0.93242
239.312	   113.85000      0.13842   63.7539   20.00000 0.93207
239.971	   114.18000      0.14253   63.7504   20.00000 0.93173
240.63	   114.51000      0.14507   63.7468   20.00000 0.93138
241.286	   114.84000      0.14839   63.7392   20.00000 0.93104
241.943	   115.17000      0.15112   63.7401   20.00000 0.93069
242.602	   115.50000      0.15356   63.7406   20.00000 0.93035
243.263	   115.83000      0.15532   63.7347   20.00000 0.93000
243.923	   116.16000      0.15728   63.7345   20.00000 0.92966
244.581	   116.49000      0.15894   63.73   20.00000 0.92931
245.24	   116.82000      0.16040   63.7202   20.00000 0.92897
245.901	   117.15000      0.16118   63.7067   20.00000 0.92862
246.561	   117.48000      0.16226   63.711   20.00000 0.92827
247.221	   117.81000      0.16255   63.7143   20.00000 0.92793
247.879	   118.14000      0.16382   63.712   20.00000 0.92759
248.534	   118.47000      0.16460   63.7044   20.00000 0.92724
249.19	   118.80000      0.16519   63.7095   20.00000 0.92690
249.845	   119.13000      0.16558   63.7092   20.00000 0.92655
250.502	   119.46000      0.16597   63.7067   20.00000 0.92621
251.158	   119.79000      0.16656   63.7141   20.00000 0.92587
251.813	   120.12000      0.16724   63.7119   20.00000 0.92553
252.465	   120.45000      0.16714   63.7065   20.00000 0.92518
253.12	   120.78000      0.16744   63.7035   20.00000 0.92484
253.776	   121.11000      0.16783   63.7076   20.00000 0.92450
254.431	   121.44000      0.16841   63.7047   20.00000 0.92416
255.088	   121.77000      0.16880   63.6988   20.00000 0.92382
255.746	   122.10000      0.16929   63.6941   20.00000 0.92348
256.405	   122.43000      0.16910   63.697   20.00000 0.92314
257.059	   122.76000      0.16851   63.7021   20.00000 0.92280
257.713	   123.09000      0.16978   63.6825   20.00000 0.92246
258.368	   123.42000      0.16949   63.687   20.00000 0.92212
259.026	   123.75000      0.16919   63.6807   20.00000 0.92178
259.686	   124.08000      0.16939   63.6871   20.00000 0.92144
260.345	   124.41000      0.16959   63.6835   20.00000 0.92110
261.002	   124.74000      0.17017   63.6894   20.00000 0.92076
261.657	   125.07000      0.17056   63.6812   20.00000 0.92042
262.313	   125.40000      0.17017   63.6807   20.00000 0.92008
262.97	   125.73000      0.17066   63.6838   20.00000 0.91974
263.627	   126.06000      0.17046   63.6788   20.00000 0.91940
264.284	   126.39000      0.17046   63.6816   20.00000 0.91906
264.941	   126.72000      0.17056   63.6789   20.00000 0.91872
265.597	   127.05000      0.17027   63.6779   20.00000 0.91838
266.252	   127.38000      0.17046   63.6884   20.00000 0.91805
266.908	   127.71000      0.17037   63.6851   20.00000 0.91771
267.563	   128.04000      0.17115   63.6815   20.00000 0.91737
268.217	   128.37000      0.17027   63.6778   20.00000 0.91703
268.871	   128.70000      0.17086   63.6823   20.00000 0.91670
269.526	   129.03000      0.16978   63.6767   20.00000 0.91636
270.184	   129.36000      0.16978   63.6841   20.00000 0.91602
270.842	   129.69000      0.16939   63.684   20.00000 0.91569
271.501	   130.02000      0.16929   63.6829   20.00000 0.91535
272.158	   130.35000      0.16919   63.6856   20.00000 0.91502
272.815	   130.68000      0.16949   63.683   20.00000 0.91468
273.47	   131.01000      0.17007   63.682   20.00000 0.91434
274.124	   131.34000      0.16968   63.6844   20.00000 0.91400
274.779	   131.67000      0.16919   63.6809   20.00000 0.91367
275.435	   132.00000      0.16890   63.6783   20.00000 0.91333
276.092	   132.33000      0.16939   63.6836   20.00000 0.91300
276.749	   132.66000      0.16812   63.6734   20.00000 0.91266
277.405	   132.99000      0.16929   63.6779   20.00000 0.91233
278.064	   133.32000      0.16890   63.6799   20.00000 0.91200
278.723	   133.65000      0.16900   63.6774   20.00000 0.91166
279.381	   133.98000      0.16910   63.673   20.00000 0.91133
280.038	   134.31000      0.16832   63.681   20.00000 0.91099
280.696	   134.64000      0.16832   63.6818   20.00000 0.91066
281.353	   134.97000      0.16832   63.6835   20.00000 0.91032
282.01	   135.30000      0.16861   63.683   20.00000 0.90999
282.664	   135.63000      0.16871   63.682   20.00000 0.90965
283.321	   135.96000      0.16773   63.6778   20.00000 0.90932
283.977	   136.29000      0.16832   63.6812   20.00000 0.90899
284.634	   136.62000      0.16792   63.6751   20.00000 0.90865
285.29	   136.95000      0.16812   63.6784   20.00000 0.90832
285.947	   137.28000      0.16763   63.6806   20.00000 0.90799
286.603	   137.61000      0.16763   63.682   20.00000 0.90766
287.259	   137.94000      0.16773   63.6764   20.00000 0.90733
287.914	   138.27000      0.16792   63.666   20.00000 0.90699
288.57	   138.60000      0.16763   63.6637   20.00000 0.90666
289.224	   138.93000      0.16734   63.6662   20.00000 0.90633
289.88	   139.26000      0.16773   63.6652   20.00000 0.90600
290.534	   139.59000      0.16792   63.6711   20.00000 0.90567
291.185	   139.92000      0.16744   63.6596   20.00000 0.90534
291.835	   140.25000      0.16744   63.6603   20.00000 0.90501
292.487	   140.58000      0.16724   63.6593   20.00000 0.90468
293.142	   140.91000      0.16714   63.6631   20.00000 0.90435
293.799	   141.24000      0.16724   63.665   20.00000 0.90402
294.455	   141.57000      0.16665   63.6676   20.00000 0.90370
295.115	   141.90000      0.16734   63.6525   20.00000 0.90337
295.775	   142.23000      0.16656   63.6593   20.00000 0.90304
296.436	   142.56000      0.16656   63.6639   20.00000 0.90271
297.093	   142.89000      0.16734   63.6633   20.00000 0.90238
297.749	   143.22000      0.16744   63.6662   20.00000 0.90205
298.404	   143.55000      0.16665   63.6691   20.00000 0.90172
299.058	   143.88000      0.16675   63.6727   20.00000 0.90139
299.713	   144.21000      0.16734   63.6709   20.00000 0.90106
300.368	   144.54000      0.16685   63.6711   20.00000 0.90074
301.023	   144.87000      0.16675   63.6839   20.00000 0.90041
301.678	   145.20000      0.16695   63.6735   20.00000 0.90008
302.334	   145.53000      0.16636   63.6735   20.00000 0.89976
302.991	   145.86000      0.16529   63.6715   20.00000 0.89943
303.647	   146.19000      0.16617   63.6682   20.00000 0.89911
304.302	   146.52000      0.16587   63.6641   20.00000 0.89878
304.958	   146.85000      0.16529   63.6605   20.00000 0.89845
305.613	   147.18000      0.16607   63.6524   20.00000 0.89813
306.266	   147.51000      0.16578   63.6573   20.00000 0.89780
306.918	   147.84000      0.16587   63.6569   20.00000 0.89748
307.57	   148.17000      0.16509   63.6515   20.00000 0.89715
308.222	   148.50000      0.16548   63.661   20.00000 0.89683
308.877	   148.83000      0.16558   63.6597   20.00000 0.89650
309.531	   149.16000      0.16617   63.6582   20.00000 0.89618
310.186	   149.49000      0.16548   63.6565   20.00000 0.89586
310.84	   149.82000      0.16519   63.6608   20.00000 0.89554
311.495	   150.15000      0.16558   63.6635   20.00000 0.89521
312.147	   150.48000      0.16441   63.6557   20.00000 0.89489
312.802	   150.81000      0.16421   63.6512   20.00000 0.89457
313.457	   151.14000      0.16441   63.6537   20.00000 0.89425
314.115	   151.47000      0.16509   63.6525   20.00000 0.89392
314.766	   151.80000      0.16451   63.6543   20.00000 0.89360
315.417	   152.13000      0.16402   63.6635   20.00000 0.89328
316.07	   152.46000      0.16421   63.6639   20.00000 0.89296
316.727	   152.79000      0.16451   63.6624   20.00000 0.89264
317.383	   153.12000      0.16392   63.6674   20.00000 0.89232
318.037	   153.45000      0.16480   63.6577   20.00000 0.89200
318.69	   153.78000      0.16431   63.675   20.00000 0.89168
319.343	   154.11000      0.16441   63.666   20.00000 0.89136
319.994	   154.44000      0.16412   63.6733   20.00000 0.89104
320.648	   154.77000      0.16314   63.6772   20.00000 0.89072
321.302	   155.10000      0.16353   63.6694   20.00000 0.89040
321.956	   155.43000      0.16353   63.6792   20.00000 0.89008
322.611	   155.76000      0.16392   63.6723   20.00000 0.88976
323.264	   156.09000      0.16314   63.6695   20.00000 0.88944
323.92	   156.42000      0.16363   63.6683   20.00000 0.88912
324.575	   156.75000      0.16353   63.675   20.00000 0.88880
325.231	   157.08000      0.16402   63.6762   20.00000 0.88849
325.884	   157.41000      0.16363   63.6752   20.00000 0.88817
326.536	   157.74000      0.16314   63.6718   20.00000 0.88785
327.187	   158.07000      0.16353   63.6767   20.00000 0.88753
327.841	   158.40000      0.16284   63.6764   20.00000 0.88721
328.496	   158.73000      0.16294   63.6728   20.00000 0.88690
329.151	   159.06000      0.16324   63.6817   20.00000 0.88658
329.807	   159.39000      0.16275   63.6806   20.00000 0.88627
330.464	   159.72000      0.16275   63.6792   20.00000 0.88595
331.121	   160.05000      0.16236   63.6799   20.00000 0.88563
331.775	   160.38000      0.16197   63.6828   20.00000 0.88532
332.428	   160.71000      0.16167   63.6796   20.00000 0.88500
333.082	   161.04000      0.16255   63.6958   20.00000 0.88468
333.735	   161.37000      0.16187   63.6845   20.00000 0.88437
334.39	   161.70000      0.16187   63.6851   20.00000 0.88405
335.043	   162.03000      0.16158   63.6905   20.00000 0.88374
335.697	   162.36000      0.16245   63.687   20.00000 0.88342
336.349	   162.69000      0.16167   63.6932   20.00000 0.88311
337.002	   163.02000      0.16177   63.6847   20.00000 0.88280
337.654	   163.35000      0.16070   63.6742   20.00000 0.88248
337.98	   163.51500      0.16132   63.6734   20.00000 0.88233