File: src/bin/Termo/Example Data/10.txt
#FILE:                       	VA_130312_Cu_10_Ar.ngb-ss1
#FORMAT:                     	NETZSCH5
#IDENTITY:                   	VA_130312_Cu_10_Ar
#DECIMAL:                    	POINT
#SEPARATOR:                  	TAB
#MTYPE:                      	DSC
#INSTRUMENT:                 	NETZSCH STA 449F1
#PROJECT:                    	oxide hydroxide
#DATE/TIME:                  	12.03.2013 14:19:20
#CORR. FILE:
#LABORATORY:                 	Нанотех
#OPERATOR:                   	Compositers
#REMARK:
#SAMPLE:                     	VA_130312_Cu_10_Ar
#SAMPLE MASS /mg:            	7.10
#MATERIAL:                   	MxOy.kH2O
#REFERENCE:
#REFERENCE MASS /mg:         	0
#TYPE OF CRUCIBLE:           	DSC/TG pan Pt-Rh
#SAMPLE CRUCIBLE MASS /mg:   	183.71
#REFERENCE CRUCIBLE MASS /mg:	185
#CORR. CODE:                 	000
#EXO:                        	+1
#RANGE:                      	20/10.0(K/min)/350
#SEGMENT:                    	S1/1

##Temp./°C	Time/min	DSC/(mW/mg)	Mass/%	Gas Flow(protective)/(ml/min)	Sensit./(uV/mW)
  21.909	    	    0.00000	     0.26782	100.00000   	20.00000	1.05000
  22.529	    	    1.04671	     0.22602	100.0001   	20.00000	1.04966
  23.149	    	    1.32264	     0.19601	100.0002   	20.00000	1.04932
  23.769	    	    1.52971	     0.17090	100.0003   	20.00000	1.04898
  24.389	    	    1.70400	     0.15216	100.00228   	20.00000	1.04864
  25.009	    	    1.85893	     0.13523	99.99786   	20.00000	1.04830
  25.629	    	    2.00146	     0.12132	99.99831   	20.00000	1.04796
  26.249	    	    2.13454	     0.10848	100.0011   	20.00000	1.04762
  26.869	    	    2.26010	 9.6020e-002	100.00214   	20.00000	1.04728
  27.489	    	    2.37985	 8.5105e-002	99.99984   	20.00000	1.04694
  28.109	    	    2.49492	 7.5268e-002	100.00035   	20.00000	1.04660
  28.729	    	    2.60587	 6.6490e-002	99.99767   	20.00000	1.04626
  29.349	    	    2.71312	 5.8157e-002	99.99837   	20.00000	1.04592
  29.969	    	    2.81755	 5.0326e-002	100.00214   	20.00000	1.04558
  30.589	    	    2.91938	 4.2112e-002	99.99765   	20.00000	1.04524
  31.209	    	    3.01870	 3.6147e-002	99.99847   	20.00000	1.04490
  31.829	    	    3.11587	 2.8923e-002	99.99878   	20.00000	1.04456
  32.449	    	    3.21115	 2.3568e-002	99.99845   	20.00000	1.04422
  33.069	    	    3.30477	 1.6492e-002	100.00036   	20.00000	1.04388
  33.689	    	    3.39697	 1.0873e-002	100.00079   	20.00000	1.04354
  34.309	    	    3.48773	 5.4525e-003	99.99996   	20.00000	1.04320
  34.929	    	    3.57711	-1.0211e-003	99.99943   	20.00000	1.04286
  35.549	    	    3.66520	-6.0820e-003	99.99756   	20.00000	1.04252
  36.169	    	    3.75214	-1.1130e-002	99.99586   	20.00000	1.04218
  36.789	    	    3.83796	-1.5642e-002	99.99892   	20.00000	1.04184
  37.409	    	    3.92280	-2.1178e-002	99.99807   	20.00000	1.04150
  38.029	    	    4.00679	-2.7911e-002	99.99811   	20.00000	1.04116
  38.649	    	    4.09001	-3.3038e-002	99.99618   	20.00000	1.04081
  39.269	    	    4.17247	-3.8295e-002	99.99655   	20.00000	1.04047
  39.889	    	    4.25409	-4.4434e-002	99.9972   	20.00000	1.04013
  40.509	    	    4.33490	-5.0428e-002	100.00084   	20.00000	1.03979
  41.129	    	    4.41492	-5.7475e-002	100.00123   	20.00000	1.03945
  41.749	    	    4.49431	-6.6411e-002	100.0005   	20.00000	1.03911
  42.369	    	    4.57311	-8.0481e-002	100.00209   	20.00000	1.03877
  42.989	    	    4.65137	    -0.10570	99.99493   	20.00000	1.03843
  43.609	    	    4.72920	    -0.14043	99.97018   	20.00000	1.03809
  44.229	    	    4.80660	    -0.17764	99.9453   	20.00000	1.03775
  44.849	    	    4.88366	    -0.21208	99.92223   	20.00000	1.03741
  45.469	    	    4.96027	    -0.24328	99.89702   	20.00000	1.03706
  46.089	    	    5.03639	    -0.27147	99.86051   	20.00000	1.03672
  46.709	    	    5.11196	    -0.29887	99.81902   	20.00000	1.03638
  47.329	    	    5.18710	    -0.32632	99.77829   	20.00000	1.03604
  47.949	    	    5.26194	    -0.35253	99.73328   	20.00000	1.03570
  48.569	    	    5.33636	    -0.37948	99.68502   	20.00000	1.03536
  49.189	    	    5.41041	    -0.40619	99.63274   	20.00000	1.03502
  49.809	    	    5.48409	    -0.43342	99.5764   	20.00000	1.03468
  50.429	    	    5.55747	    -0.46170	99.51457   	20.00000	1.03433
  51.049	    	    5.63049	    -0.48977	99.4502   	20.00000	1.03399
  51.669	    	    5.70324	    -0.51761	99.38053   	20.00000	1.03365
  52.289	    	    5.77566	    -0.54811	99.30559   	20.00000	1.03331
  52.909	    	    5.84783	    -0.57754	99.23067   	20.00000	1.03297
  53.529	    	    5.91963	    -0.60663	99.1553   	20.00000	1.03263
  54.149	    	    5.99109	    -0.63901	99.07917   	20.00000	1.03229
  54.769	    	    6.06214	    -0.67064	98.99873   	20.00000	1.03195
  55.389	    	    6.13293	    -0.70437	98.91467   	20.00000	1.03160
  56.009	    	    6.20361	    -0.73656	98.81481   	20.00000	1.03126
  56.629	    	    6.27421	    -0.77031	98.71465   	20.00000	1.03092
  57.249	    	    6.34453	    -0.80443	98.6131   	20.00000	1.03058
  57.869	    	    6.41444	    -0.83877	98.50547   	20.00000	1.03024
  58.489	    	    6.48400	    -0.87653	98.39409   	20.00000	1.02990
  59.109	    	    6.55335	    -0.91242	98.28706   	20.00000	1.02956
  59.729	    	    6.62246	    -0.95001	98.16014   	20.00000	1.02921
  60.349	    	    6.69130	    -0.98740	98.04203   	20.00000	1.02887
  60.969	    	    6.75994	    -1.02707	97.92159   	20.00000	1.02853
  61.589	    	    6.82851	    -1.06667	97.78297   	20.00000	1.02819
  62.209	    	    6.89697	    -1.10467	97.63601   	20.00000	1.02785
  62.829	    	    6.96528	    -1.14710	97.48337   	20.00000	1.02751
  63.449	    	    7.03337	    -1.18857	97.33214   	20.00000	1.02716
  64.069	    	    7.10130	    -1.23004	97.17826   	20.00000	1.02682
  64.689	    	    7.16897	    -1.27280	97.02361   	20.00000	1.02648
  65.309	    	    7.23654	    -1.31705	96.859   	20.00000	1.02614
  65.929	    	    7.30405	    -1.36228	96.68958   	20.00000	1.02580
  66.549	    	    7.37169	    -1.40661	96.51072   	20.00000	1.02546
  67.169	    	    7.43925	    -1.45381	96.32425   	20.00000	1.02511
  67.789	    	    7.50668	    -1.50150	96.13286   	20.00000	1.02477
  68.409	    	    7.57382	    -1.55056	95.93496   	20.00000	1.02443
  69.029	    	    7.64078	    -1.59925	95.73362   	20.00000	1.02409
  69.649	    	    7.70764	    -1.64898	95.52333   	20.00000	1.02375
  70.269	    	    7.77454	    -1.70130	95.30713   	20.00000	1.02341
  70.889	    	    7.84143	    -1.75397	95.08156   	20.00000	1.02306
  71.509	    	    7.90848	    -1.80784	94.83835   	20.00000	1.02272
  72.129	    	    7.97564	    -1.86368	94.58428   	20.00000	1.02238
  72.749	    	    8.04303	    -1.92179	94.32498   	20.00000	1.02204
  73.369	    	    8.11031	    -1.98042	94.0499   	20.00000	1.02170
  73.989	    	    8.17740	    -2.04162	93.75885   	20.00000	1.02136
  74.609	    	    8.24416	    -2.10258	93.45031   	20.00000	1.02101
  75.229	    	    8.31073	    -2.16501	93.11998   	20.00000	1.02067
  75.849	    	    8.37718	    -2.22760	92.82448   	20.00000	1.02033
  76.469	    	    8.44353	    -2.29119	92.52801   	20.00000	1.01999
  77.089	    	    8.50985	    -2.35543	92.21656   	20.00000	1.01965
  77.709	    	    8.57608	    -2.41970	91.89008   	20.00000	1.01931
  78.329	    	    8.64228	    -2.48140	91.55881   	20.00000	1.01897
  78.949	    	    8.70849	    -2.54407	91.21325   	20.00000	1.01862
  79.569	    	    8.77465	    -2.60328	90.87128   	20.00000	1.01828
  80.189	    	    8.84081	    -2.65925	90.50741   	20.00000	1.01794
  80.809	    	    8.90675	    -2.71199	90.15055   	20.00000	1.01760
  81.429	    	    8.97252	    -2.75904	89.7664   	20.00000	1.01726
  82.049	    	    9.03799	    -2.79764	89.3889   	20.00000	1.01692
  82.669	    	    9.10335	    -2.82681	89.0007   	20.00000	1.01657
  83.289	    	    9.16856	    -2.84813	88.6219   	20.00000	1.01623
  83.909	    	    9.23366	    -2.85636	88.2485   	20.00000	1.01589
  84.529	    	    9.29849	    -2.85026	87.8754   	20.00000	1.01555
  85.149	    	    9.36296	    -2.82589	87.5149   	20.00000	1.01521
  85.769	    	    9.42702	    -2.78188	87.1914   	20.00000	1.01487
  86.389	    	    9.49067	    -2.71253	86.8689   	20.00000	1.01452
  87.009	    	    9.55393	    -2.62209	86.5986   	20.00000	1.01418
  87.629	    	    9.61678	    -2.50944	86.3919   	20.00000	1.01384
  88.249	    	    9.67918	    -2.36416	86.2062   	20.00000	1.01350
  88.869	    	    9.74113	    -2.17679	86.0884   	20.00000	1.01316
  89.489	    	    9.80260	    -1.94843	85.9855   	20.00000	1.01282
  90.109	    	    9.86352	    -1.69608	85.9147   	20.00000	1.01248
  90.729	    	    9.92386	    -1.44374	85.8725   	20.00000	1.01213
  91.349	    	    9.98364	    -1.20919	85.8449   	20.00000	1.01179
  91.969	    	   10.04295	    -1.01016	85.8258   	20.00000	1.01145
  92.589	    	   10.10196	    -0.84971	85.8107   	20.00000	1.01111
  93.209	    	   10.16077	    -0.71840	85.7955   	20.00000	1.01077
  93.829	    	   10.21949	    -0.61654	85.78   	20.00000	1.01043
  94.449	    	   10.27820	    -0.53633	85.7696   	20.00000	1.01009
  95.069	    	   10.33688	    -0.47176	85.7607   	20.00000	1.00974
  95.689	    	   10.39562	    -0.42517	85.7485   	20.00000	1.00940
  96.309	    	   10.45434	    -0.38757	85.7381   	20.00000	1.00906
  96.929	    	   10.51310	    -0.35983	85.7269   	20.00000	1.00872
  97.549	    	   10.57194	    -0.34024	85.7135   	20.00000	1.00838
  98.169	    	   10.63090	    -0.32512	85.6998   	20.00000	1.00804
  98.789	    	   10.68995	    -0.31757	85.6904   	20.00000	1.00770
  99.409	    	   10.74909	    -0.31139	85.6823   	20.00000	1.00736
  100.029	    	   10.80823	    -0.31112	85.6708   	20.00000	1.00702
  100.649	    	   10.86742	    -0.31373	85.6592   	20.00000	1.00667
  101.269	    	   10.92667	    -0.31908	85.6474   	20.00000	1.00633
  101.889	    	   10.98600	    -0.32739	85.6336   	20.00000	1.00599
  102.509	    	   11.04545	    -0.33840	85.6169   	20.00000	1.00565
  103.129	    	   11.10499	    -0.35081	85.5941   	20.00000	1.00531
  103.749	    	   11.16462	    -0.36749	85.5545   	20.00000	1.00497
  104.369	    	   11.22425	    -0.39070	85.5161   	20.00000	1.00463
  104.989	    	   11.28391	    -0.43622	85.4545   	20.00000	1.00429
  105.609	    	   11.34372	    -0.56714	85.337   	20.00000	1.00395
  106.229	    	   11.40414	    -0.77881	85.043   	20.00000	1.00361
  106.849	    	   11.46548	    -1.22390	84.6952   	20.00000	1.00326
  107.469	    	   11.52804	    -1.87081	84.2008   	20.00000	1.00292
  108.089	    	   11.59177	    -2.50279	83.651   	20.00000	1.00258
  108.709	    	   11.65661	    -3.07600	83.0561   	20.00000	1.00224
  109.329	    	   11.72265	    -3.57872	82.4521   	20.00000	1.00190
  109.949	    	   11.78972	    -4.00796	81.813   	20.00000	1.00156
  110.569	    	   11.85766	    -4.36907	81.1616   	20.00000	1.00122
  111.189	    	   11.92598	    -4.66998	80.4894   	20.00000	1.00088
  111.809	    	   11.99436	    -4.91713	79.8068   	20.00000	1.00054
  112.429	    	   12.06246	    -5.11136	79.127   	20.00000	1.00020
  113.049	    	   12.13012	    -5.25697	78.4392   	20.00000	0.99986
  113.669	    	   12.19732	    -5.36042	77.761   	20.00000	0.99952
  114.289	    	   12.26404	    -5.41743	77.0944   	20.00000	0.99918
  114.909	    	   12.33023	    -5.43596	76.4582   	20.00000	0.99884
  115.529	    	   12.39581	    -5.41283	75.8529   	20.00000	0.99850
  116.149	    	   12.46057	    -5.35478	75.2712   	20.00000	0.99816
  116.769	    	   12.52450	    -5.26627	74.7362   	20.00000	0.99782
  117.389	    	   12.58770	    -5.14938	74.2528   	20.00000	0.99748
  118.009	    	   12.65042	    -5.00848	73.8144   	20.00000	0.99714
  118.629	    	   12.71283	    -4.84295	73.4401   	20.00000	0.99680
  119.249	    	   12.77489	    -4.65165	73.1266   	20.00000	0.99646
  119.869	    	   12.83653	    -4.43708	72.8499   	20.00000	0.99612
  120.489	    	   12.89763	    -4.19765	72.6183   	20.00000	0.99578
  121.109	    	   12.95814	    -3.93426	72.4255   	20.00000	0.99544
  121.729	    	   13.01808	    -3.65379	72.268   	20.00000	0.99510
  122.349	    	   13.07741	    -3.35973	72.1423   	20.00000	0.99476
  122.969	    	   13.13622	    -3.06064	72.0334   	20.00000	0.99442
  123.589	    	   13.19459	    -2.76545	71.929   	20.00000	0.99408
  124.209	    	   13.25252	    -2.47627	71.8557   	20.00000	0.99374
  124.829	    	   13.31010	    -2.19514	71.8011   	20.00000	0.99340
  125.449	    	   13.36732	    -1.92648	71.7564   	20.00000	0.99306
  126.069	    	   13.42422	    -1.67391	71.7237   	20.00000	0.99272
  126.689	    	   13.48086	    -1.43948	71.6997   	20.00000	0.99238
  127.309	    	   13.53729	    -1.22563	71.68   	20.00000	0.99204
  127.929	    	   13.59359	    -1.03670	71.6627   	20.00000	0.99170
  128.549	    	   13.64984	    -0.87200	71.6502   	20.00000	0.99136
  129.169	    	   13.70614	    -0.73148	71.6414   	20.00000	0.99102
  129.789	    	   13.76256	    -0.62059	71.6323   	20.00000	0.99068
  130.409	    	   13.81915	    -0.53212	71.624   	20.00000	0.99034
  131.029	    	   13.87589	    -0.46083	71.6163   	20.00000	0.99000
  131.649	    	   13.93279	    -0.40619	71.6111   	20.00000	0.98966
  132.269	    	   13.98976	    -0.36401	71.6062   	20.00000	0.98932
  132.889	    	   14.04676	    -0.33212	71.602   	20.00000	0.98898
  133.509	    	   14.10379	    -0.30518	71.6007   	20.00000	0.98865
  134.129	    	   14.16087	    -0.28468	71.5961   	20.00000	0.98831
  134.749	    	   14.21808	    -0.26940	71.5877   	20.00000	0.98797
  135.369	    	   14.27543	    -0.25732	71.5781   	20.00000	0.98763
  135.989	    	   14.33293	    -0.24666	71.5713   	20.00000	0.98729
  136.609	    	   14.39052	    -0.23903	71.567   	20.00000	0.98695
  137.229	    	   14.44813	    -0.23484	71.5656   	20.00000	0.98661
  137.849	    	   14.50571	    -0.22894	71.5582   	20.00000	0.98627
  138.469	    	   14.56328	    -0.22555	71.5519   	20.00000	0.98594
  139.089	    	   14.62088	    -0.22279	71.5519   	20.00000	0.98560
  139.709	    	   14.67852	    -0.22013	71.5467   	20.00000	0.98526
  140.329	    	   14.73615	    -0.21810	71.5407   	20.00000	0.98492
  140.949	    	   14.79370	    -0.21681	71.5351   	20.00000	0.98458
  141.569	    	   14.85118	    -0.21539	71.5289   	20.00000	0.98424
  142.189	    	   14.90864	    -0.21504	71.5242   	20.00000	0.98391
  142.809	    	   14.96629	    -0.21410	71.5223   	20.00000	0.98357
  143.429	    	   15.02412	    -0.21377	71.5197   	20.00000	0.98323
  144.049	    	   15.08217	    -0.21305	71.5188   	20.00000	0.98289
  144.669	    	   15.14032	    -0.21185	71.5222   	20.00000	0.98255
  145.289	    	   15.19846	    -0.21210	71.5203   	20.00000	0.98222
  145.909	    	   15.25656	    -0.21270	71.5169   	20.00000	0.98188
  146.529	    	   15.31455	    -0.21241	71.5124   	20.00000	0.98154
  147.149	    	   15.37251	    -0.21222	71.5089   	20.00000	0.98120
  147.769	    	   15.43047	    -0.21224	71.5056   	20.00000	0.98086
  148.389	    	   15.48853	    -0.21320	71.5033   	20.00000	0.98053
  149.009	    	   15.54668	    -0.21242	71.501   	20.00000	0.98019
  149.629	    	   15.60489	    -0.21209	71.4953   	20.00000	0.97985
  150.249	    	   15.66313	    -0.21220	71.4893   	20.00000	0.97951
  150.869	    	   15.72141	    -0.21352	71.4847   	20.00000	0.97918
  151.489	    	   15.77977	    -0.21287	71.483   	20.00000	0.97884
  152.109	    	   15.83815	    -0.21255	71.4828   	20.00000	0.97850
  152.729	    	   15.89653	    -0.21276	71.4799   	20.00000	0.97817
  153.349	    	   15.95484	    -0.21319	71.4755   	20.00000	0.97783
  153.969	    	   16.01303	    -0.21398	71.4716   	20.00000	0.97749
  154.589	    	   16.07114	    -0.21361	71.4665   	20.00000	0.97716
  155.209	    	   16.12918	    -0.21385	71.4623   	20.00000	0.97682
  155.829	    	   16.18730	    -0.21380	71.4624   	20.00000	0.97648
  156.449	    	   16.24552	    -0.21452	71.4601   	20.00000	0.97615
  157.069	    	   16.30380	    -0.21527	71.4548   	20.00000	0.97581
  157.689	    	   16.36211	    -0.21515	71.4574   	20.00000	0.97547
  158.309	    	   16.42040	    -0.21486	71.4593   	20.00000	0.97514
  158.929	    	   16.47875	    -0.21529	71.4597   	20.00000	0.97480
  159.549	    	   16.53716	    -0.21556	71.4587   	20.00000	0.97446
  160.169	    	   16.59566	    -0.21611	71.4593   	20.00000	0.97413
  160.789	    	   16.65420	    -0.21680	71.458   	20.00000	0.97379
  161.409	    	   16.71280	    -0.21699	71.4524   	20.00000	0.97345
  162.029	    	   16.77139	    -0.21745	71.4445   	20.00000	0.97312
  162.649	    	   16.82996	    -0.21772	71.4395   	20.00000	0.97278
  163.269	    	   16.88848	    -0.21767	71.4337   	20.00000	0.97245
  163.889	    	   16.94697	    -0.21831	71.4093   	20.00000	0.97211
  164.509	    	   17.00551	    -0.21923	71.4141   	20.00000	0.97178
  165.129	    	   17.06410	    -0.21896	71.412   	20.00000	0.97144
  165.749	    	   17.12274	    -0.21906	71.4101   	20.00000	0.97110
  166.369	    	   17.18139	    -0.21938	71.4079   	20.00000	0.97077
  166.989	    	   17.24006	    -0.22013	71.4051   	20.00000	0.97043
  167.609	    	   17.29879	    -0.22083	71.4008   	20.00000	0.97010
  168.229	    	   17.35758	    -0.22127	71.3972   	20.00000	0.96976
  168.849	    	   17.41638	    -0.22097	71.3974   	20.00000	0.96943
  169.469	    	   17.47515	    -0.22122	71.4004   	20.00000	0.96909
  170.089	    	   17.53392	    -0.22213	71.4028   	20.00000	0.96876
  170.709	    	   17.59271	    -0.22255	71.403   	20.00000	0.96842
  171.329	    	   17.65158	    -0.22193	71.3972   	20.00000	0.96809
  171.949	    	   17.71049	    -0.22285	71.3897   	20.00000	0.96775
  172.569	    	   17.76937	    -0.22305	71.3861   	20.00000	0.96742
  173.189	    	   17.82823	    -0.22273	71.3826   	20.00000	0.96709
  173.809	    	   17.88707	    -0.22318	71.3776   	20.00000	0.96675
  174.429	    	   17.94596	    -0.22417	71.3754   	20.00000	0.96642
  175.049	    	   18.00489	    -0.22390	71.3755   	20.00000	0.96608
  175.669	    	   18.06379	    -0.22455	71.3738   	20.00000	0.96575
  176.289	    	   18.12262	    -0.22508	71.3712   	20.00000	0.96541
  176.909	    	   18.18143	    -0.22529	71.3694   	20.00000	0.96508
  177.529	    	   18.24028	    -0.22543	71.3715   	20.00000	0.96475
  178.149	    	   18.29925	    -0.22574	71.3681   	20.00000	0.96441
  178.769	    	   18.35830	    -0.22628	71.3598   	20.00000	0.96408
  179.389	    	   18.41736	    -0.22616	71.3568   	20.00000	0.96375
  180.009	    	   18.47637	    -0.22757	71.3524   	20.00000	0.96341
  180.629	    	   18.53536	    -0.22761	71.3502   	20.00000	0.96308
  181.249	    	   18.59427	    -0.22796	71.3513   	20.00000	0.96275
  181.869	    	   18.65320	    -0.22888	71.3506   	20.00000	0.96241
  182.489	    	   18.71208	    -0.22958	71.3464   	20.00000	0.96208
  183.109	    	   18.77096	    -0.22967	71.3385   	20.00000	0.96175
  183.729	    	   18.82984	    -0.23080	71.3288   	20.00000	0.96141
  184.349	    	   18.88869	    -0.23114	71.3227   	20.00000	0.96108
  184.969	    	   18.94756	    -0.23181	71.3199   	20.00000	0.96075
  185.589	    	   19.00641	    -0.23143	71.3202   	20.00000	0.96042
  186.209	    	   19.06523	    -0.23303	71.3205   	20.00000	0.96008
  186.829	    	   19.12401	    -0.23385	71.3199   	20.00000	0.95975
  187.449	    	   19.18274	    -0.23437	71.3218   	20.00000	0.95942
  188.069	    	   19.24144	    -0.23541	71.3226   	20.00000	0.95909
  188.689	    	   19.30016	    -0.23604	71.3197   	20.00000	0.95875
  189.309	    	   19.35892	    -0.23696	71.3123   	20.00000	0.95842
  189.929	    	   19.41778	    -0.23807	71.301   	20.00000	0.95809
  190.549	    	   19.47667	    -0.23895	71.2923   	20.00000	0.95776
  191.169	    	   19.53553	    -0.23876	71.2872   	20.00000	0.95743
  191.789	    	   19.59429	    -0.23980	71.2814   	20.00000	0.95710
  192.409	    	   19.65297	    -0.24147	71.2729   	20.00000	0.95676
  193.029	    	   19.71163	    -0.24208	71.2678   	20.00000	0.95643
  193.649	    	   19.77039	    -0.24264	71.2662   	20.00000	0.95610
  194.269	    	   19.82922	    -0.24349	71.2634   	20.00000	0.95577
  194.889	    	   19.88807	    -0.24532	71.2584   	20.00000	0.95544
  195.509	    	   19.94690	    -0.24728	71.2535   	20.00000	0.95511
  196.129	    	   20.00569	    -0.24702	71.2492   	20.00000	0.95478
  196.749	    	   20.06446	    -0.24771	71.243   	20.00000	0.95445
  197.369	    	   20.12319	    -0.24886	71.2337   	20.00000	0.95412
  197.989	    	   20.18191	    -0.25061	71.2259   	20.00000	0.95379
  198.609	    	   20.24067	    -0.25179	71.2177   	20.00000	0.95345
  199.229	    	   20.29947	    -0.25447	71.2066   	20.00000	0.95312
  199.849	    	   20.35836	    -0.25680	71.1934   	20.00000	0.95279
  200.469	    	   20.41728	    -0.26166	71.18   	20.00000	0.95246
  201.089	    	   20.47620	    -0.26863	71.1647   	20.00000	0.95213
  201.709	    	   20.53509	    -0.27786	71.1479   	20.00000	0.95180
  202.329	    	   20.59396	    -0.28994	71.1289   	20.00000	0.95147
  202.949	    	   20.65287	    -0.30448	71.1061   	20.00000	0.95114
  203.569	    	   20.71187	    -0.32401	71.0816   	20.00000	0.95082
  204.189	    	   20.77095	    -0.34752	71.0556   	20.00000	0.95049
  204.809	    	   20.83010	    -0.37337	71.0278   	20.00000	0.95016
  205.429	    	   20.88923	    -0.40198	70.9957   	20.00000	0.94983
  206.049	    	   20.94834	    -0.43477	70.9624   	20.00000	0.94950
  206.669	    	   21.00745	    -0.46835	70.9206   	20.00000	0.94917
  207.289	    	   21.06657	    -0.50220	70.8772   	20.00000	0.94884
  207.909	    	   21.12581	    -0.53793	70.8324   	20.00000	0.94851
  208.529	    	   21.18516	    -0.57274	70.7803   	20.00000	0.94818
  209.149	    	   21.24463	    -0.60677	70.7265   	20.00000	0.94785
  209.769	    	   21.30419	    -0.64168	70.6692   	20.00000	0.94753
  210.389	    	   21.36382	    -0.67565	70.6097   	20.00000	0.94720
  211.009	    	   21.42339	    -0.71127	70.5511   	20.00000	0.94687
  211.629	    	   21.48289	    -0.74344	70.488   	20.00000	0.94654
  212.249	    	   21.54232	    -0.77815	70.4246   	20.00000	0.94621
  212.869	    	   21.60172	    -0.81287	70.3589   	20.00000	0.94589
  213.489	    	   21.66116	    -0.84728	70.2939   	20.00000	0.94556
  214.109	    	   21.72069	    -0.88269	70.2205   	20.00000	0.94523
  214.729	    	   21.78030	    -0.91592	70.1422   	20.00000	0.94490
  215.349	    	   21.83999	    -0.95411	70.064   	20.00000	0.94458
  215.969	    	   21.89970	    -0.98887	69.9857   	20.00000	0.94425
  216.589	    	   21.95942	    -1.02461	69.9014   	20.00000	0.94392
  217.209	    	   22.01914	    -1.06182	69.8101   	20.00000	0.94360
  217.829	    	   22.07880	    -1.09942	69.7158   	20.00000	0.94327
  218.449	    	   22.13842	    -1.13621	69.6211   	20.00000	0.94294
  219.069	    	   22.19805	    -1.17248	69.527   	20.00000	0.94262
  219.689	    	   22.25769	    -1.20950	69.4282   	20.00000	0.94229
  220.309	    	   22.31739	    -1.24786	69.3264   	20.00000	0.94196
  220.929	    	   22.37714	    -1.28395	69.2237   	20.00000	0.94164
  221.549	    	   22.43697	    -1.32096	69.1198   	20.00000	0.94131
  222.169	    	   22.49684	    -1.35741	69.014   	20.00000	0.94098
  222.789	    	   22.55677	    -1.39208	68.9024   	20.00000	0.94066
  223.409	    	   22.61672	    -1.42787	68.7906   	20.00000	0.94033
  224.029	    	   22.67672	    -1.46301	68.6775   	20.00000	0.94001
  224.649	    	   22.73670	    -1.49762	68.5646   	20.00000	0.93968
  225.269	    	   22.79667	    -1.53103	68.4464   	20.00000	0.93936
  225.889	    	   22.85659	    -1.56404	68.3304   	20.00000	0.93903
  226.509	    	   22.91652	    -1.59480	68.2029   	20.00000	0.93871
  227.129	    	   22.97644	    -1.62661	68.0744   	20.00000	0.93838
  227.749	    	   23.03641	    -1.65474	67.9457   	20.00000	0.93806
  228.369	    	   23.09635	    -1.68358	67.8217   	20.00000	0.93773
  228.989	    	   23.15627	    -1.71195	67.7006   	20.00000	0.93741
  229.609	    	   23.21613	    -1.73624	67.5743   	20.00000	0.93708
  230.229	    	   23.27596	    -1.75929	67.4454   	20.00000	0.93676
  230.849	    	   23.33578	    -1.77913	67.3171   	20.00000	0.93644
  231.469	    	   23.39561	    -1.79951	67.1867   	20.00000	0.93611
  232.089	    	   23.45547	    -1.81940	67.0592   	20.00000	0.93579
  232.709	    	   23.51536	    -1.83273	66.9322   	20.00000	0.93546
  233.329	    	   23.57526	    -1.84480	66.807   	20.00000	0.93514
  233.949	    	   23.63515	    -1.85482	66.6823   	20.00000	0.93482
  234.569	    	   23.69498	    -1.86190	66.5626   	20.00000	0.93449
  235.189	    	   23.75475	    -1.86631	66.4467   	20.00000	0.93417
  235.809	    	   23.81443	    -1.86665	66.3292   	20.00000	0.93385
  236.429	    	   23.87399	    -1.86349	66.209   	20.00000	0.93352
  237.049	    	   23.93350	    -1.85655	66.0942   	20.00000	0.93320
  237.669	    	   23.99299	    -1.84607	65.9789   	20.00000	0.93288
  238.289	    	   24.05249	    -1.83069	65.8689   	20.00000	0.93256
  238.909	    	   24.11202	    -1.81345	65.7576   	20.00000	0.93223
  239.529	    	   24.17147	    -1.79123	65.6535   	20.00000	0.93191
  240.149	    	   24.23093	    -1.76596	65.5539   	20.00000	0.93159
  240.769	    	   24.29037	    -1.73629	65.4592   	20.00000	0.93127
  241.389	    	   24.34992	    -1.70317	65.3672   	20.00000	0.93095
  242.009	    	   24.40944	    -1.66727	65.2809   	20.00000	0.93063
  242.629	    	   24.46879	    -1.62643	65.1986   	20.00000	0.93030
  243.249	    	   24.52791	    -1.58390	65.1194   	20.00000	0.92998
  243.869	    	   24.58684	    -1.53851	65.0465   	20.00000	0.92966
  244.489	    	   24.64575	    -1.49079	64.9798   	20.00000	0.92934
  245.109	    	   24.70463	    -1.44223	64.9126   	20.00000	0.92902
  245.729	    	   24.76335	    -1.39037	64.8519   	20.00000	0.92870
  246.349	    	   24.82187	    -1.33928	64.7956   	20.00000	0.92838
  246.969	    	   24.88019	    -1.28467	64.7378   	20.00000	0.92806
  247.589	    	   24.93853	    -1.23219	64.6873   	20.00000	0.92774
  248.209	    	   24.99695	    -1.17759	64.6444   	20.00000	0.92742
  248.829	    	   25.05542	    -1.12393	64.6016   	20.00000	0.92710
  249.449	    	   25.11393	    -1.06885	64.5581   	20.00000	0.92678
  250.069	    	   25.17237	    -1.01588	64.5196   	20.00000	0.92646
  250.689	    	   25.23079	    -0.96177	64.4905   	20.00000	0.92614
  251.309	    	   25.28917	    -0.91000	64.464   	20.00000	0.92582
  251.929	    	   25.34751	    -0.85884	64.4351   	20.00000	0.92550
  252.549	    	   25.40588	    -0.81026	64.4102   	20.00000	0.92518
  253.169	    	   25.46423	    -0.76168	64.3862   	20.00000	0.92486
  253.789	    	   25.52262	    -0.71647	64.3632   	20.00000	0.92454
  254.409	    	   25.58102	    -0.67205	64.3447   	20.00000	0.92422
  255.029	    	   25.63943	    -0.63033	64.3303   	20.00000	0.92391
  255.649	    	   25.69784	    -0.58994	64.313   	20.00000	0.92359
  256.269	    	   25.75623	    -0.55187	64.2957   	20.00000	0.92327
  256.889	    	   25.81462	    -0.51703	64.2842   	20.00000	0.92295
  257.509	    	   25.87300	    -0.48460	64.2753   	20.00000	0.92263
  258.129	    	   25.93139	    -0.45368	64.2632   	20.00000	0.92232
  258.749	    	   25.98982	    -0.42545	64.2488   	20.00000	0.92200
  259.369	    	   26.04829	    -0.39847	64.2404   	20.00000	0.92168
  259.989	    	   26.10680	    -0.37514	64.2357   	20.00000	0.92136
  260.609	    	   26.16535	    -0.35186	64.2295   	20.00000	0.92105
  261.229	    	   26.22390	    -0.33265	64.2214   	20.00000	0.92073
  261.849	    	   26.28245	    -0.31431	64.2178   	20.00000	0.92041
  262.469	    	   26.34101	    -0.29688	64.2154   	20.00000	0.92010
  263.089	    	   26.39962	    -0.28082	64.2125   	20.00000	0.91978
  263.709	    	   26.45830	    -0.26744	64.2068   	20.00000	0.91946
  264.329	    	   26.51699	    -0.25629	64.2019   	20.00000	0.91915
  264.949	    	   26.57569	    -0.24453	64.1981   	20.00000	0.91883
  265.569	    	   26.63435	    -0.23534	64.1938   	20.00000	0.91852
  266.189	    	   26.69298	    -0.22748	64.1913   	20.00000	0.91820
  266.809	    	   26.75161	    -0.22125	64.1891   	20.00000	0.91789
  267.429	    	   26.81026	    -0.21485	64.1871   	20.00000	0.91757
  268.049	    	   26.86899	    -0.20798	64.1852   	20.00000	0.91725
  268.669	    	   26.92774	    -0.20351	64.1821   	20.00000	0.91694
  269.289	    	   26.98655	    -0.19865	64.1809   	20.00000	0.91662
  269.909	    	   27.04541	    -0.19372	64.1834   	20.00000	0.91631
  270.529	    	   27.10429	    -0.19043	64.1869   	20.00000	0.91600
  271.149	    	   27.16318	    -0.18689	64.1881   	20.00000	0.91568
  271.769	    	   27.22204	    -0.18399	64.1874   	20.00000	0.91537
  272.389	    	   27.28089	    -0.18167	64.1878   	20.00000	0.91505
  273.009	    	   27.33976	    -0.17938	64.1914   	20.00000	0.91474
  273.629	    	   27.39869	    -0.17693	64.1965   	20.00000	0.91443
  274.249	    	   27.45772	    -0.17559	64.198   	20.00000	0.91411
  274.869	    	   27.51683	    -0.17434	64.1933   	20.00000	0.91380
  275.489	    	   27.57600	    -0.17245	64.1846   	20.00000	0.91349
  276.109	    	   27.63519	    -0.17062	64.1788   	20.00000	0.91317
  276.729	    	   27.69434	    -0.16940	64.1777   	20.00000	0.91286
  277.349	    	   27.75348	    -0.16723	64.1773   	20.00000	0.91255
  277.969	    	   27.81257	    -0.16691	64.1757   	20.00000	0.91223
  278.589	    	   27.87168	    -0.16511	64.1751   	20.00000	0.91192
  279.209	    	   27.93081	    -0.16454	64.1762   	20.00000	0.91161
  279.829	    	   27.98999	    -0.16355	64.1765   	20.00000	0.91130
  280.449	    	   28.04919	    -0.16254	64.1756   	20.00000	0.91099
  281.069	    	   28.10842	    -0.16190	64.1752   	20.00000	0.91068
  281.689	    	   28.16766	    -0.16133	64.1774   	20.00000	0.91036
  282.309	    	   28.22693	    -0.16086	64.1789   	20.00000	0.91005
  282.929	    	   28.28621	    -0.16002	64.1789   	20.00000	0.90974
  283.549	    	   28.34549	    -0.15961	64.1801   	20.00000	0.90943
  284.169	    	   28.40475	    -0.15815	64.1815   	20.00000	0.90912
  284.789	    	   28.46403	    -0.15850	64.1809   	20.00000	0.90881
  285.409	    	   28.52335	    -0.15801	64.1796   	20.00000	0.90850
  286.029	    	   28.58272	    -0.15766	64.1795   	20.00000	0.90819
  286.649	    	   28.64209	    -0.15734	64.1796   	20.00000	0.90788
  287.269	    	   28.70144	    -0.15734	64.1785   	20.00000	0.90757
  287.889	    	   28.76078	    -0.15621	64.1787   	20.00000	0.90726
  288.509	    	   28.82007	    -0.15663	64.1851   	20.00000	0.90695
  289.129	    	   28.87939	    -0.15679	64.1827   	20.00000	0.90664
  289.749	    	   28.93869	    -0.15674	64.1769   	20.00000	0.90633
  290.369	    	   28.99800	    -0.15611	64.1767   	20.00000	0.90602
  290.989	    	   29.05734	    -0.15572	64.1761   	20.00000	0.90571
  291.609	    	   29.11671	    -0.15491	64.1763   	20.00000	0.90540
  292.229	    	   29.17615	    -0.15577	64.1769   	20.00000	0.90510
  292.849	    	   29.23566	    -0.15474	64.1772   	20.00000	0.90479
  293.469	    	   29.29520	    -0.15433	64.1776   	20.00000	0.90448
  294.089	    	   29.35473	    -0.15519	64.1802   	20.00000	0.90417
  294.709	    	   29.41423	    -0.15496	64.1832   	20.00000	0.90386
  295.329	    	   29.47372	    -0.15487	64.1821   	20.00000	0.90356
  295.949	    	   29.53322	    -0.15494	64.1775   	20.00000	0.90325
  296.569	    	   29.59273	    -0.15430	64.178   	20.00000	0.90294
  297.189	    	   29.65226	    -0.15435	64.1818   	20.00000	0.90263
  297.809	    	   29.71181	    -0.15505	64.1751   	20.00000	0.90233
  298.429	    	   29.77141	    -0.15409	64.169   	20.00000	0.90202
  299.049	    	   29.83103	    -0.15408	64.1663   	20.00000	0.90171
  299.669	    	   29.89068	    -0.15463	64.1681   	20.00000	0.90141
  300.289	    	   29.95027	    -0.15407	64.1714   	20.00000	0.90110
  300.909	    	   30.00986	    -0.15461	64.171   	20.00000	0.90080
  301.529	    	   30.06947	    -0.15383	64.1736   	20.00000	0.90049
  302.149	    	   30.12909	    -0.15463	64.1775   	20.00000	0.90019
  302.769	    	   30.18872	    -0.15494	64.1781   	20.00000	0.89988
  303.389	    	   30.24830	    -0.15497	64.1758   	20.00000	0.89957
  304.009	    	   30.30788	    -0.15514	64.1734   	20.00000	0.89927
  304.629	    	   30.36744	    -0.15535	64.1728   	20.00000	0.89897
  305.249	    	   30.42703	    -0.15509	64.1728   	20.00000	0.89866
  305.869	    	   30.48659	    -0.15518	64.1737   	20.00000	0.89836
  306.489	    	   30.54622	    -0.15482	64.1741   	20.00000	0.89805
  307.109	    	   30.60587	    -0.15558	64.1746   	20.00000	0.89775
  307.729	    	   30.66559	    -0.15581	64.1771   	20.00000	0.89744
  308.349	    	   30.72531	    -0.15606	64.1854   	20.00000	0.89714
  308.969	    	   30.78496	    -0.15528	64.1884   	20.00000	0.89684
  309.589	    	   30.84459	    -0.15620	64.1783   	20.00000	0.89653
  310.209	    	   30.90418	    -0.15631	64.1717   	20.00000	0.89623
  310.829	    	   30.96381	    -0.15621	64.1627   	20.00000	0.89593
  311.449	    	   31.02345	    -0.15629	64.1613   	20.00000	0.89563
  312.069	    	   31.08311	    -0.15558	64.1631   	20.00000	0.89532
  312.689	    	   31.14278	    -0.15601	64.1642   	20.00000	0.89502
  313.309	    	   31.20253	    -0.15569	64.1642   	20.00000	0.89472
  313.929	    	   31.26236	    -0.15585	64.1661   	20.00000	0.89442
  314.549	    	   31.32217	    -0.15671	64.1687   	20.00000	0.89412
  315.169	    	   31.38188	    -0.15570	64.1709   	20.00000	0.89381
  315.789	    	   31.44137	    -0.15631	64.1732   	20.00000	0.89351
  316.409	    	   31.50081	    -0.15691	64.174   	20.00000	0.89321
  317.029	    	   31.56028	    -0.15679	64.1738   	20.00000	0.89291
  317.649	    	   31.61986	    -0.15614	64.1736   	20.00000	0.89261
  318.269	    	   31.67952	    -0.15642	64.1719   	20.00000	0.89231
  318.889	    	   31.73921	    -0.15688	64.167   	20.00000	0.89201
  319.509	    	   31.79893	    -0.15710	64.1634   	20.00000	0.89171
  320.129	    	   31.85868	    -0.15657	64.1632   	20.00000	0.89141
  320.749	    	   31.91845	    -0.15680	64.1633   	20.00000	0.89111
  321.369	    	   31.97819	    -0.15710	64.1632   	20.00000	0.89081
  321.989	    	   32.03794	    -0.15658	64.1641   	20.00000	0.89051
  322.609	    	   32.09767	    -0.15683	64.1662   	20.00000	0.89021
  323.229	    	   32.15740	    -0.15695	64.1676   	20.00000	0.88991
  323.849	    	   32.21719	    -0.15658	64.1695   	20.00000	0.88961
  324.469	    	   32.27699	    -0.15728	64.1684   	20.00000	0.88932
  325.089	    	   32.33683	    -0.15651	64.1678   	20.00000	0.88902
  325.709	    	   32.39673	    -0.15655	64.1682   	20.00000	0.88872
  326.329	    	   32.45663	    -0.15699	64.1672   	20.00000	0.88842
  326.949	    	   32.51654	    -0.15660	64.1654   	20.00000	0.88812
  327.569	    	   32.57644	    -0.15686	64.1624   	20.00000	0.88783
  328.189	    	   32.63633	    -0.15736	64.1578   	20.00000	0.88753