File: Example Data/05.txt
#FILE:VA_130315_Cu_05_Ar.ngb-ss1
#FORMAT:NETZSCH5
#IDENTITY:VA_130315_Cu_05_Ar
#DECIMAL:POINT
#SEPARATOR:SEMICOLON
#MTYPE:DSC
#INSTRUMENT:NETZSCH STA 449F1
#PROJECT:oxide hydroxide
#DATE/TIME:15.03.2013 9:59:01
#CORR. FILE:
#LABORATORY:Нанотех
#OPERATOR:Compositers
#REMARK:
#SAMPLE:VA_130315_Cu_05_Ar
#SAMPLE MASS /mg:7.69
#MATERIAL:MxOy.kH2O
#REFERENCE:
#REFERENCE MASS /mg:0
#TYPE OF CRUCIBLE:DSC/TG pan Pt-Rh
#SAMPLE CRUCIBLE MASS /mg:183.70
#REFERENCE CRUCIBLE MASS /mg:185
#CORR. CODE:000
#EXO:+1
#RANGE:20/5.0(K/min)/350
#SEGMENT:S1/1

##Temp./°C;Time/min;DSC/(mW/mg);Mass/%;Gas Flow(protective)/(ml/min);Sensit./(uV/mW)
 22.579	     0.00000      0.24748   100.00000    20.00000 1.04993
 22.5996	     0.13200      0.24835   100.0004    20.00000 1.04993
 22.6016	     0.26400      0.24737   100.00043    20.00000 1.04993
 22.6071	     0.39600      0.24686   100.00054    20.00000 1.04992
 22.6185	     0.52800      0.24625   100.00076    20.00000 1.04992
 22.6378	     0.66000      0.24493   100.00113    20.00000 1.04990
 22.6684	     0.79200      0.24195   100.00172    20.00000 1.04988
 22.7148	     0.92400      0.23944   100.00261    20.00000 1.04985
 22.7788	     1.05600      0.23582   100.00384    20.00000 1.04981
 22.8611	     1.18800      0.23070   100.00542    20.00000 1.04976
 22.9648	     1.32000      0.22599   100.00741    20.00000 1.04969
 23.0896	     1.45200      0.22016   100.00981    20.00000 1.04961
 23.2339	     1.58400      0.21324   100.01259    20.00000 1.04952
 23.3994	     1.71600      0.20952   100.01577    20.00000 1.04942
 23.5834	     1.84800      0.20301   99.98939    20.00000 1.04931
 23.7912	     1.98000      0.19744   99.97563    20.00000 1.04919
 24.0184	     2.11200      0.19096   99.97796    20.00000 1.04905
 24.267	     2.24400      0.18569   99.9758    20.00000 1.04890
 24.5318	     2.37600      0.17973   99.97755    20.00000 1.04875
 24.815	     2.50800      0.17531   99.98618    20.00000 1.04858
 25.1144	     2.64000      0.16986   100.00137    20.00000 1.04841
 25.4306	     2.77200      0.16585   100.00077    20.00000 1.04822
 25.7609	     2.90400      0.16160   99.99387    20.00000 1.04803
 26.1042	     3.03600      0.15759   99.99041    20.00000 1.04783
 26.463	     3.16800      0.15291   99.98786    20.00000 1.04763
 26.8369	     3.30000      0.14852   99.98556    20.00000 1.04742
 27.2205	     3.43200      0.14649   99.99244    20.00000 1.04720
 27.6127	     3.56400      0.14294   99.99798    20.00000 1.04697
 28.012	     3.69600      0.13790   100.00415    20.00000 1.04674
 28.4242	     3.82800      0.13532   100.0123    20.00000 1.04651
 28.8477	     3.96000      0.13152   100.00247    20.00000 1.04627
 29.2811	     4.09200      0.12923   99.99773    20.00000 1.04602
 29.722	     4.22400      0.12573   99.99719    20.00000 1.04577
 30.1716	     4.35600      0.12353   99.99507    20.00000 1.04552
 30.6323	     4.48800      0.11996   99.9932    20.00000 1.04526
 31.1016	     4.62000      0.11811   99.99454    20.00000 1.04500
 31.5754	     4.75200      0.11410   100.00599    20.00000 1.04473
 32.0547	     4.88400      0.11231   100.01191    20.00000 1.04446
 32.5429	     5.01600      0.10906   100.00912    20.00000 1.04419
 33.0376	     5.14800      0.10695   100.00795    20.00000 1.04391
 33.5398	     5.28000      0.10476   100.00536    20.00000 1.04363
 34.0453	     5.41200      0.10156   100.00582    20.00000 1.04334
 34.5611	     5.54400  9.8370e-002   100.00509    20.00000 1.04305
 35.0818	     5.67600  9.7163e-002   100.00451    20.00000 1.04276
 35.6093	     5.80800  9.3725e-002   99.99265    20.00000 1.04246
 36.1401	     5.94000  9.1866e-002   99.99352    20.00000 1.04216
 36.6736	     6.07200  8.9408e-002   99.9961    20.00000 1.04186
 37.2111	     6.20400  8.6275e-002   99.9971    20.00000 1.04156
 37.7537	     6.33600  8.3366e-002   99.9989    20.00000 1.04126
 38.3025	     6.46800  7.9990e-002   99.99993    20.00000 1.04095
 38.856	     6.60000  7.7223e-002   99.99636    20.00000 1.04064
 39.4136	     6.73200  7.3568e-002   99.99802    20.00000 1.04033
 39.9746	     6.86400  6.9152e-002   99.99031    20.00000 1.04002
 40.5367	     6.99600  6.3593e-002   99.98247    20.00000 1.03970
 41.0988	     7.12800  5.5997e-002   99.96302    20.00000 1.03938
 41.6619	     7.26000  3.7524e-002   99.93764    20.00000 1.03906
 42.2325	     7.39200  1.6609e-002   99.91204    20.00000 1.03874
 42.8042	     7.52400 -1.1501e-003   99.87859    20.00000 1.03842
 43.3796	     7.65600 -2.0476e-002   99.84135    20.00000 1.03810
 43.9561	     7.78800 -3.8887e-002   99.79877    20.00000 1.03778
 44.537	     7.92000 -5.9960e-002   99.74845    20.00000 1.03745
 45.1209	     8.05200 -7.8311e-002   99.7001    20.00000 1.03713
 45.7042	     8.18400 -9.6790e-002   99.65205    20.00000 1.03680
 46.2899	     8.31600     -0.11423   99.59505    20.00000 1.03647
 46.8766	     8.44800     -0.13034   99.53327    20.00000 1.03614
 47.4658	     8.58000     -0.14683   99.46155    20.00000 1.03581
 48.0582	     8.71200     -0.16435   99.38726    20.00000 1.03548
 48.6509	     8.84400     -0.18250   99.31314    20.00000 1.03515
 49.2437	     8.97600     -0.20046   99.23    20.00000 1.03482
 49.8384	     9.10800     -0.22040   99.13994    20.00000 1.03448
 50.4356	     9.24000     -0.23965   99.04138    20.00000 1.03415
 51.0355	     9.37200     -0.25928   98.93621    20.00000 1.03381
 51.6343	     9.50400     -0.28030   98.8248    20.00000 1.03348
 52.235	     9.63600     -0.30241   98.71376    20.00000 1.03314
 52.8366	     9.76800     -0.32654   98.58203    20.00000 1.03280
 53.4406	     9.90000     -0.34997   98.45761    20.00000 1.03246
 54.0455	    10.03200     -0.37514   98.31951    20.00000 1.03212
 54.6509	    10.16400     -0.40122   98.18146    20.00000 1.03178
 55.2582	    10.29600     -0.42821   98.0301    20.00000 1.03144
 55.8657	    10.42800     -0.45646   97.86824    20.00000 1.03110
 56.4743	    10.56000     -0.48626   97.70187    20.00000 1.03076
 57.0846	    10.69200     -0.51670   97.52598    20.00000 1.03041
 57.6978	    10.82400     -0.54796   97.35056    20.00000 1.03007
 58.3109	    10.95600     -0.58026   97.15936    20.00000 1.02973
 58.9258	    11.08800     -0.61523   96.95337    20.00000 1.02939
 59.5402	    11.22000     -0.65145   96.73962    20.00000 1.02905
 60.1564	    11.35200     -0.68898   96.51356    20.00000 1.02870
 60.7738	    11.48400     -0.72747   96.2943    20.00000 1.02836
 61.3919	    11.61600     -0.76754   96.0525    20.00000 1.02802
 62.0108	    11.74800     -0.81012   95.80551    20.00000 1.02768
 62.6284	    11.88000     -0.85322   95.55133    20.00000 1.02733
 63.2473	    12.01200     -0.89855   95.28092    20.00000 1.02699
 63.8711	    12.14400     -0.94483   94.98633    20.00000 1.02664
 64.4972	    12.27600     -0.99232   94.68752    20.00000 1.02630
 65.1237	    12.40800     -1.04126   94.3897    20.00000 1.02595
 65.7462	    12.54000     -1.09069   94.07611    20.00000 1.02560
 66.3673	    12.67200     -1.14142   93.74367    20.00000 1.02526
 66.9867	    12.80400     -1.19089   93.41107    20.00000 1.02491
 67.6046	    12.93600     -1.24316   93.05277    20.00000 1.02457
 68.2244	    13.06800     -1.29522   92.69365    20.00000 1.02423
 68.8431	    13.20000     -1.34669   92.32059    20.00000 1.02388
 69.4622	    13.33200     -1.39741   91.93842    20.00000 1.02354
 70.0803	    13.46400     -1.44731   91.54133    20.00000 1.02319
 70.6984	    13.59600     -1.49660   91.14298    20.00000 1.02285
 71.3192	    13.72800     -1.54411   90.73135    20.00000 1.02250
 71.9401	    13.86000     -1.59064   90.31033    20.00000 1.02216
 72.5601	    13.99200     -1.63496   89.8716    20.00000 1.02181
 73.1802	    14.12400     -1.68072   89.4263    20.00000 1.02146
 73.8041	    14.25600     -1.72306   88.9764    20.00000 1.02112
 74.433	    14.38800     -1.76597   88.5315    20.00000 1.02077
 75.0676	    14.52000     -1.80578   88.0718    20.00000 1.02043
 75.7043	    14.65200     -1.84073   87.6105    20.00000 1.02008
 76.3483	    14.78400     -1.86740   87.1025    20.00000 1.01974
 76.9977	    14.91600     -1.87691   86.6656    20.00000 1.01939
 77.6559	    15.04800     -1.85442   86.2899    20.00000 1.01904
 78.3262	    15.18000     -1.77117   85.9883    20.00000 1.01869
 79.0085	    15.31200     -1.56908   85.7909    20.00000 1.01833
 79.6984	    15.44400     -1.13059   85.7071    20.00000 1.01796
 80.3893	    15.57600     -0.68185   85.6766    20.00000 1.01758
 81.0774	    15.70800     -0.40523   85.6541    20.00000 1.01719
 81.7613	    15.84000     -0.23983   85.6324    20.00000 1.01680
 82.4428	    15.97200     -0.14542   85.619    20.00000 1.01641
 83.1208	    16.10400 -8.6077e-002   85.6086    20.00000 1.01602
 83.7981	    16.23600 -4.9707e-002   85.5969    20.00000 1.01563
 84.4719	    16.36800 -2.8513e-002   85.5825    20.00000 1.01525
 85.1461	    16.50000 -1.6130e-002   85.5667    20.00000 1.01487
 85.8157	    16.63200 -9.5488e-003   85.5497    20.00000 1.01449
 86.4855	    16.76400 -5.7180e-003   85.5372    20.00000 1.01411
 87.1563	    16.89600 -4.0775e-003   85.5261    20.00000 1.01373
 87.8252	    17.02800 -3.3904e-003   85.5159    20.00000 1.01336
 88.4955	    17.16000 -3.8197e-003   85.5076    20.00000 1.01298
 89.1615	    17.29200 -6.0610e-003   85.4989    20.00000 1.01260
 89.8304	    17.42400 -7.8593e-003   85.4892    20.00000 1.01223
 90.4979	    17.55600 -9.6552e-003   85.4804    20.00000 1.01185
 91.1666	    17.68800 -1.3012e-002   85.4717    20.00000 1.01148
 91.8349	    17.82000 -1.6288e-002   85.4574    20.00000 1.01111
 92.5016	    17.95200 -2.0046e-002   85.4428    20.00000 1.01073
 93.1692	    18.08400 -2.3653e-002   85.4313    20.00000 1.01036
 93.836	    18.21600 -2.7510e-002   85.4169    20.00000 1.00999
 94.5045	    18.34800 -3.2184e-002   85.3982    20.00000 1.00962
 95.1732	    18.48000 -3.6471e-002   85.3815    20.00000 1.00924
 95.8393	    18.61200 -4.1917e-002   85.3627    20.00000 1.00887
 96.5018	    18.74400 -4.6277e-002   85.3434    20.00000 1.00850
 97.1655	    18.87600 -5.3073e-002   85.3208    20.00000 1.00813
 97.8321	    19.00800 -5.8363e-002   85.2975    20.00000 1.00776
 98.502	    19.14000 -6.6576e-002   85.2733    20.00000 1.00738
 99.1678	    19.27200 -7.6663e-002   85.2513    20.00000 1.00701
 99.8298	    19.40400 -9.0070e-002   85.2213    20.00000 1.00664
 100.48	    19.53600     -0.12223   85.1496    20.00000 1.00627
 101.112	    19.66800     -0.29781   84.9777    20.00000 1.00591
 101.716	    19.80000     -0.67990   84.5116    20.00000 1.00555
 102.294	    19.93200     -1.50283   83.8305    20.00000 1.00521
 102.855	    20.06400     -2.15683   83.0934    20.00000 1.00489
 103.413	    20.19600     -2.59113   82.333    20.00000 1.00457
 103.975	    20.32800     -2.88452   81.5505    20.00000 1.00426
 104.545	    20.46000     -3.08046   80.7403    20.00000 1.00395
 105.123	    20.59200     -3.20179   79.9217    20.00000 1.00364
 105.711	    20.72400     -3.26633   79.1092    20.00000 1.00332
 106.311	    20.85600     -3.28052   78.2975    20.00000 1.00299
 106.921	    20.98800     -3.24847   77.5245    20.00000 1.00266
 107.541	    21.12000     -3.18584   76.7891    20.00000 1.00232
 108.171	    21.25200     -3.10625   76.0736    20.00000 1.00198
 108.808	    21.38400     -3.03729   75.4027    20.00000 1.00163
 109.453	    21.51600     -2.98558   74.7387    20.00000 1.00128
 110.11	    21.64800     -2.94309   74.1404    20.00000 1.00093
 110.774	    21.78000     -2.88610   73.5704    20.00000 1.00058
 111.448	    21.91200     -2.78032   73.0549    20.00000 1.00022
 112.133	    22.04400     -2.59308   72.6399    20.00000 0.99986
 112.827	    22.17600     -2.30592   72.2935    20.00000 0.99949
 113.53	    22.30800     -1.93628   72.0667    20.00000 0.99911
 114.238	    22.44000     -1.53111   71.8781    20.00000 0.99873
 114.951	    22.57200     -1.12345   71.7604    20.00000 0.99833
 115.665	    22.70400     -0.76260   71.69    20.00000 0.99793
 116.379	    22.83600     -0.48857   71.6485    20.00000 0.99753
 117.093	    22.96800     -0.30272   71.6169    20.00000 0.99712
 117.803	    23.10000     -0.18395   71.5966    20.00000 0.99672
 118.505	    23.23200     -0.11169   71.579    20.00000 0.99632
 119.205	    23.36400 -6.3521e-002   71.5626    20.00000 0.99593
 119.9	    23.49600 -3.7458e-002   71.5471    20.00000 0.99553
 120.594	    23.62800 -1.8615e-002   71.53    20.00000 0.99514
 121.286	    23.76000 -7.6796e-003   71.5214    20.00000 0.99476
 121.976	    23.89200  1.6365e-004   71.5187    20.00000 0.99437
 122.662	    24.02400  4.1755e-003   71.5154    20.00000 0.99398
 123.348	    24.15600  8.3787e-003   71.5126    20.00000 0.99360
 124.031	    24.28800  9.9293e-003   71.5052    20.00000 0.99322
 124.713	    24.42000  1.2691e-002   71.505    20.00000 0.99284
 125.394	    24.55200  1.4581e-002   71.4901    20.00000 0.99246
 126.075	    24.68400  1.4865e-002   71.4834    20.00000 0.99208
 126.753	    24.81600  1.6155e-002   71.4781    20.00000 0.99170
 127.431	    24.94800  1.6268e-002   71.4676    20.00000 0.99132
 128.108	    25.08000  1.6920e-002   71.4619    20.00000 0.99095
 128.785	    25.21200  1.6916e-002   71.4592    20.00000 0.99057
 129.462	    25.34400  1.8115e-002   71.4603    20.00000 0.99020
 130.137	    25.47600  1.8141e-002   71.4493    20.00000 0.98982
 130.813	    25.60800  1.8416e-002   71.4448    20.00000 0.98945
 131.487	    25.74000  1.8557e-002   71.4464    20.00000 0.98907
 132.162	    25.87200  1.9169e-002   71.4527    20.00000 0.98870
 132.834	    26.00400  1.8345e-002   71.4298    20.00000 0.98833
 133.507	    26.13600  1.8534e-002   71.4335    20.00000 0.98795
 134.179	    26.26800  1.8306e-002   71.4359    20.00000 0.98758
 134.852	    26.40000  1.7889e-002   71.4254    20.00000 0.98721
 135.523	    26.53200  1.7825e-002   71.414    20.00000 0.98683
 136.192	    26.66400  1.8898e-002   71.4076    20.00000 0.98646
 136.861	    26.79600  1.8354e-002   71.4094    20.00000 0.98609
 137.53	    26.92800  1.8511e-002   71.4144    20.00000 0.98572
 138.199	    27.06000  1.8124e-002   71.4121    20.00000 0.98535
 138.869	    27.19200  1.8574e-002   71.4078    20.00000 0.98497
 139.538	    27.32400  1.7927e-002   71.4117    20.00000 0.98460
 140.206	    27.45600  1.7420e-002   71.4031    20.00000 0.98423
 140.875	    27.58800  1.7822e-002   71.3932    20.00000 0.98386
 141.544	    27.72000  1.7250e-002   71.3947    20.00000 0.98349
 142.217	    27.85200  1.6840e-002   71.3978    20.00000 0.98312
 142.887	    27.98400  1.6342e-002   71.399    20.00000 0.98275
 143.555	    28.11600  1.6240e-002   71.3891    20.00000 0.98238
 144.223	    28.24800  1.5912e-002   71.3872    20.00000 0.98201
 144.89	    28.38000  1.5868e-002   71.3796    20.00000 0.98164
 145.557	    28.51200  1.5965e-002   71.38    20.00000 0.98127
 146.224	    28.64400  1.5539e-002   71.3746    20.00000 0.98090
 146.893	    28.77600  1.5102e-002   71.3658    20.00000 0.98053
 147.564	    28.90800  1.5465e-002   71.3639    20.00000 0.98016
 148.232	    29.04000  1.4277e-002   71.3705    20.00000 0.97980
 148.9	    29.17200  1.4001e-002   71.3747    20.00000 0.97943
 149.568	    29.30400  1.4069e-002   71.3668    20.00000 0.97906
 150.237	    29.43600  1.3696e-002   71.3605    20.00000 0.97869
 150.907	    29.56800  1.3313e-002   71.3541    20.00000 0.97832
 151.576	    29.70000  1.3087e-002   71.3534    20.00000 0.97796
 152.245	    29.83200  1.2748e-002   71.3572    20.00000 0.97759
 152.913	    29.96400  1.2975e-002   71.3468    20.00000 0.97722
 153.581	    30.09600  1.2169e-002   71.3355    20.00000 0.97685
 154.248	    30.22800  1.1645e-002   71.3269    20.00000 0.97649
 154.917	    30.36000  1.1587e-002   71.3284    20.00000 0.97612
 155.586	    30.49200  1.1095e-002   71.3301    20.00000 0.97575
 156.256	    30.62400  1.1242e-002   71.3335    20.00000 0.97538
 156.923	    30.75600  1.0574e-002   71.3362    20.00000 0.97502
 157.591	    30.88800  1.0257e-002   71.3384    20.00000 0.97465
 158.257	    31.02000  1.0183e-002   71.3367    20.00000 0.97429
 158.924	    31.15200  9.1214e-003   71.3308    20.00000 0.97392
 159.592	    31.28400  8.6228e-003   71.32    20.00000 0.97356
 160.258	    31.41600  8.0490e-003   71.3161    20.00000 0.97319
 160.925	    31.54800  8.0454e-003   71.3163    20.00000 0.97282
 161.592	    31.68000  8.2638e-003   71.3116    20.00000 0.97246
 162.261	    31.81200  8.4812e-003   71.3101    20.00000 0.97209
 162.93	    31.94400  7.5602e-003   71.3117    20.00000 0.97173
 163.598	    32.07600  7.4943e-003   71.3083    20.00000 0.97136
 164.264	    32.20800  7.0866e-003   71.3047    20.00000 0.97100
 164.929	    32.34000  6.7461e-003   71.3041    20.00000 0.97064
 165.592	    32.47200  5.8816e-003   71.3013    20.00000 0.97027
 166.26	    32.60400  5.7758e-003   71.3034    20.00000 0.96991
 166.925	    32.73600  5.6868e-003   71.2992    20.00000 0.96955
 167.591	    32.86800  4.9840e-003   71.2926    20.00000 0.96918
 168.256	    33.00000  5.3251e-003   71.2858    20.00000 0.96882
 168.92	    33.13200  5.0511e-003   71.2842    20.00000 0.96846
 169.585	    33.26400  4.0757e-003   71.2826    20.00000 0.96809
 170.251	    33.39600  4.3568e-003   71.2842    20.00000 0.96773
 170.918	    33.52800  2.7436e-003   71.2803    20.00000 0.96737
 171.584	    33.66000  2.6675e-003   71.2803    20.00000 0.96700
 172.248	    33.79200  2.3249e-003   71.2718    20.00000 0.96664
 172.913	    33.92400  2.4303e-003   71.2738    20.00000 0.96628
 173.578	    34.05600  2.0017e-003   71.2697    20.00000 0.96592
 174.245	    34.18800  1.9184e-003   71.2588    20.00000 0.96555
 174.909	    34.32000  1.0279e-003   71.2539    20.00000 0.96519
 175.575	    34.45200  6.3095e-004   71.2536    20.00000 0.96483
 176.24	    34.58400  6.8782e-004   71.2436    20.00000 0.96447
 176.905	    34.71600 -2.0517e-005   71.2377    20.00000 0.96411
 177.57	    34.84800 -5.0472e-004   71.2353    20.00000 0.96375
 178.236	    34.98000 -1.3388e-003   71.2365    20.00000 0.96338
 178.902	    35.11200 -1.3994e-003   71.2346    20.00000 0.96302
 179.567	    35.24400 -2.7378e-003   71.2294    20.00000 0.96266
 180.231	    35.37600 -3.5230e-003   71.2264    20.00000 0.96230
 180.895	    35.50800 -3.9501e-003   71.2241    20.00000 0.96194
 181.558	    35.64000 -4.3334e-003   71.2216    20.00000 0.96158
 182.223	    35.77200 -5.7465e-003   71.2175    20.00000 0.96122
 182.889	    35.90400 -5.7026e-003   71.2098    20.00000 0.96085
 183.554	    36.03600 -6.7039e-003   71.2069    20.00000 0.96049
 184.222	    36.16800 -7.6287e-003   71.2036    20.00000 0.96013
 184.887	    36.30000 -7.8562e-003   71.1936    20.00000 0.95977
 185.552	    36.43200 -9.5068e-003   71.1859    20.00000 0.95940
 186.217	    36.56400 -9.8577e-003   71.1797    20.00000 0.95904
 186.882	    36.69600 -1.1122e-002   71.1727    20.00000 0.95868
 187.55	    36.82800 -1.1058e-002   71.1724    20.00000 0.95832
 188.218	    36.96000 -1.2532e-002   71.1679    20.00000 0.95795
 188.884	    37.09200 -1.2776e-002   71.1616    20.00000 0.95759
 189.549	    37.22400 -1.4289e-002   71.1617    20.00000 0.95723
 190.215	    37.35600 -1.5028e-002   71.1522    20.00000 0.95687
 190.882	    37.48800 -1.7681e-002   71.1434    20.00000 0.95651
 191.549	    37.62000 -1.9922e-002   71.1298    20.00000 0.95615
 192.216	    37.75200 -2.5092e-002   71.117    20.00000 0.95579
 192.883	    37.88400 -3.2446e-002   71.1084    20.00000 0.95543
 193.549	    38.01600 -4.2063e-002   71.0963    20.00000 0.95507
 194.214	    38.14800 -5.3679e-002   71.0754    20.00000 0.95471
 194.877	    38.28000 -7.0588e-002   71.0533    20.00000 0.95434
 195.542	    38.41200 -9.1077e-002   71.0273    20.00000 0.95398
 196.205	    38.54400     -0.11402   70.9997    20.00000 0.95363
 196.868	    38.67600     -0.13968   70.9718    20.00000 0.95327
 197.531	    38.80800     -0.16627   70.9245    20.00000 0.95291
 198.194	    38.94000     -0.19466   70.8793    20.00000 0.95255
 198.859	    39.07200     -0.22057   70.8375    20.00000 0.95219
 199.524	    39.20400     -0.24709   70.7945    20.00000 0.95184
 200.186	    39.33600     -0.27120   70.7387    20.00000 0.95148
 200.847	    39.46800     -0.29472   70.6851    20.00000 0.95112
 201.508	    39.60000     -0.31879   70.6261    20.00000 0.95076
 202.171	    39.73200     -0.34141   70.5636    20.00000 0.95041
 202.833	    39.86400     -0.36354   70.4935    20.00000 0.95005
 203.494	    39.99600     -0.38606   70.4145    20.00000 0.94970
 204.156	    40.12800     -0.40835   70.333    20.00000 0.94934
 204.816	    40.26000     -0.42978   70.2561    20.00000 0.94899
 205.477	    40.39200     -0.45054   70.1702    20.00000 0.94863
 206.138	    40.52400     -0.47295   70.092    20.00000 0.94828
 206.8	    40.65600     -0.49436   70.0028    20.00000 0.94793
 207.462	    40.78800     -0.51410   69.9129    20.00000 0.94757
 208.125	    40.92000     -0.53627   69.8192    20.00000 0.94722
 208.786	    41.05200     -0.55537   69.7183    20.00000 0.94686
 209.448	    41.18400     -0.57535   69.6223    20.00000 0.94651
 210.109	    41.31600     -0.59498   69.5117    20.00000 0.94616
 210.773	    41.44800     -0.61422   69.3939    20.00000 0.94580
 211.436	    41.58000     -0.63308   69.2851    20.00000 0.94545
 212.099	    41.71200     -0.65074   69.1796    20.00000 0.94510
 212.761	    41.84400     -0.66732   69.0723    20.00000 0.94474
 213.423	    41.97600     -0.68506   68.9574    20.00000 0.94439
 214.085	    42.10800     -0.70081   68.8265    20.00000 0.94403
 214.747	    42.24000     -0.71596   68.7071    20.00000 0.94368
 215.41	    42.37200     -0.73099   68.5814    20.00000 0.94333
 216.075	    42.50400     -0.74357   68.456    20.00000 0.94297
 216.741	    42.63600     -0.75705   68.3267    20.00000 0.94262
 217.406	    42.76800     -0.76926   68.1894    20.00000 0.94227
 218.07	    42.90000     -0.77944   68.0524    20.00000 0.94191
 218.733	    43.03200     -0.78845   67.9153    20.00000 0.94156
 219.398	    43.16400     -0.79650   67.7765    20.00000 0.94121
 220.066	    43.29600     -0.80194   67.6383    20.00000 0.94085
 220.733	    43.42800     -0.80615   67.504    20.00000 0.94050
 221.399	    43.56000     -0.80908   67.361    20.00000 0.94015
 222.064	    43.69200     -0.80974   67.231    20.00000 0.93980
 222.729	    43.82400     -0.80845   67.0936    20.00000 0.93944
 223.395	    43.95600     -0.80565   66.9591    20.00000 0.93909
 224.061	    44.08800     -0.79955   66.8237    20.00000 0.93874
 224.727	    44.22000     -0.79052   66.6866    20.00000 0.93838
 225.394	    44.35200     -0.77875   66.5557    20.00000 0.93803
 226.063	    44.48400     -0.76637   66.4152    20.00000 0.93767
 226.732	    44.61600     -0.75059   66.2909    20.00000 0.93732
 227.4	    44.74800     -0.73344   66.1661    20.00000 0.93697
 228.069	    44.88000     -0.71394   66.0539    20.00000 0.93661
 228.738	    45.01200     -0.69246   65.9311    20.00000 0.93626
 229.407	    45.14400     -0.67032   65.8194    20.00000 0.93590
 230.076	    45.27600     -0.64688   65.7061    20.00000 0.93555
 230.746	    45.40800     -0.62177   65.5956    20.00000 0.93519
 231.417	    45.54000     -0.59665   65.4867    20.00000 0.93484
 232.088	    45.67200     -0.57066   65.3875    20.00000 0.93449
 232.761	    45.80400     -0.54247   65.2936    20.00000 0.93413
 233.435	    45.93600     -0.51562   65.2074    20.00000 0.93377
 234.109	    46.06800     -0.48729   65.1246    20.00000 0.93342
 234.785	    46.20000     -0.45987   65.0471    20.00000 0.93307
 235.459	    46.33200     -0.43177   64.972    20.00000 0.93271
 236.133	    46.46400     -0.40561   64.8992    20.00000 0.93236
 236.805	    46.59600     -0.37775   64.8239    20.00000 0.93201
 237.479	    46.72800     -0.35352   64.7563    20.00000 0.93165
 238.153	    46.86000     -0.32673   64.6993    20.00000 0.93130
 238.826	    46.99200     -0.30262   64.6488    20.00000 0.93095
 239.5	    47.12400     -0.27820   64.5861    20.00000 0.93059
 240.169	    47.25600     -0.25433   64.5342    20.00000 0.93024
 240.839	    47.38800     -0.23382   64.4979    20.00000 0.92988
 241.507	    47.52000     -0.21336   64.4612    20.00000 0.92953
 242.179	    47.65200     -0.19258   64.4277    20.00000 0.92918
 242.852	    47.78400     -0.17510   64.3946    20.00000 0.92883
 243.527	    47.91600     -0.15733   64.3643    20.00000 0.92847
 244.203	    48.04800     -0.14102   64.342    20.00000 0.92812
 244.878	    48.18000     -0.12490   64.318    20.00000 0.92777
 245.552	    48.31200     -0.11128   64.2856    20.00000 0.92742
 246.226	    48.44400 -9.7916e-002   64.2737    20.00000 0.92707
 246.897	    48.57600 -8.5516e-002   64.2529    20.00000 0.92672
 247.569	    48.70800 -7.5308e-002   64.239    20.00000 0.92637
 248.242	    48.84000 -6.4390e-002   64.2284    20.00000 0.92602
 248.916	    48.97200 -5.4795e-002   64.22    20.00000 0.92567
 249.588	    49.10400 -4.6327e-002   64.2079    20.00000 0.92532
 250.26	    49.23600 -3.8241e-002   64.1922    20.00000 0.92497
 250.931	    49.36800 -3.1555e-002   64.1873    20.00000 0.92462
 251.603	    49.50000 -2.5118e-002   64.1899    20.00000 0.92427
 252.277	    49.63200 -1.9830e-002   64.1805    20.00000 0.92392
 252.947	    49.76400 -1.4458e-002   64.1734    20.00000 0.92357
 253.615	    49.89600 -1.0469e-002   64.1618    20.00000 0.92322
 254.28	    50.02800 -6.6110e-003   64.1584    20.00000 0.92288
 254.951	    50.16000 -3.4414e-003   64.1501    20.00000 0.92253
 255.621	    50.29200 -7.0502e-004   64.1503    20.00000 0.92218
 256.291	    50.42400  6.2999e-004   64.1433    20.00000 0.92184
 256.96	    50.55600  2.5080e-003   64.1415    20.00000 0.92149
 257.629	    50.68800  5.3300e-003   64.1419    20.00000 0.92114
 258.303	    50.82000  6.4648e-003   64.1413    20.00000 0.92080
 258.974	    50.95200  7.9344e-003   64.1351    20.00000 0.92045
 259.646	    51.08400  9.0469e-003   64.1334    20.00000 0.92011
 260.314	    51.21600  9.9390e-003   64.1316    20.00000 0.91976
 260.982	    51.34800  1.0911e-002   64.1336    20.00000 0.91942
 261.649	    51.48000  1.2090e-002   64.1335    20.00000 0.91907
 262.315	    51.61200  1.2881e-002   64.1332    20.00000 0.91873
 262.981	    51.74400  1.2203e-002   64.1278    20.00000 0.91839
 263.647	    51.87600  1.3048e-002   64.1296    20.00000 0.91804
 264.315	    52.00800  1.4151e-002   64.1325    20.00000 0.91770
 264.982	    52.14000  1.4059e-002   64.1315    20.00000 0.91736
 265.648	    52.27200  1.4029e-002   64.1302    20.00000 0.91702
 266.314	    52.40400  1.4110e-002   64.1278    20.00000 0.91667
 266.981	    52.53600  1.5092e-002   64.1336    20.00000 0.91633
 267.648	    52.66800  1.4982e-002   64.1315    20.00000 0.91599
 268.315	    52.80000  1.4086e-002   64.1257    20.00000 0.91565
 268.981	    52.93200  1.5637e-002   64.1266    20.00000 0.91530
 269.646	    53.06400  1.5207e-002   64.131    20.00000 0.91496
 270.311	    53.19600  1.5198e-002   64.1329    20.00000 0.91462
 270.977	    53.32800  1.5729e-002   64.1404    20.00000 0.91428
 271.643	    53.46000  1.5958e-002   64.1315    20.00000 0.91394
 272.309	    53.59200  1.5193e-002   64.1228    20.00000 0.91359
 272.975	    53.72400  1.5454e-002   64.1188    20.00000 0.91325
 273.641	    53.85600  1.5641e-002   64.1238    20.00000 0.91291
 274.307	    53.98800  1.6228e-002   64.1253    20.00000 0.91257
 274.972	    54.12000  1.5335e-002   64.1285    20.00000 0.91223
 275.637	    54.25200  1.5333e-002   64.1267    20.00000 0.91189
 276.302	    54.38400  1.5527e-002   64.1244    20.00000 0.91155
 276.969	    54.51600  1.5624e-002   64.1232    20.00000 0.91121
 277.634	    54.64800  1.5335e-002   64.1283    20.00000 0.91087
 278.298	    54.78000  1.5037e-002   64.1283    20.00000 0.91053
 278.963	    54.91200  1.5438e-002   64.1317    20.00000 0.91020
 279.628	    55.04400  1.5361e-002   64.1311    20.00000 0.90986
 280.293	    55.17600  1.5283e-002   64.1286    20.00000 0.90952
 280.958	    55.30800  1.5427e-002   64.1252    20.00000 0.90918
 281.623	    55.44000  1.4737e-002   64.1236    20.00000 0.90884
 282.287	    55.57200  1.4733e-002   64.1215    20.00000 0.90851
 282.95	    55.70400  1.5140e-002   64.1216    20.00000 0.90817
 283.614	    55.83600  1.4103e-002   64.1219    20.00000 0.90784
 284.28	    55.96800  1.4568e-002   64.1258    20.00000 0.90750
 284.943	    56.10000  1.4545e-002   64.1289    20.00000 0.90717
 285.606	    56.23200  1.4520e-002   64.1273    20.00000 0.90683
 286.268	    56.36400  1.4318e-002   64.1301    20.00000 0.90650
 286.932	    56.49600  1.4826e-002   64.1299    20.00000 0.90616
 287.597	    56.62800  1.3831e-002   64.1292    20.00000 0.90583
 288.261	    56.76000  1.3805e-002   64.1238    20.00000 0.90549
 288.926	    56.89200  1.3682e-002   64.1183    20.00000 0.90516
 289.589	    57.02400  1.4073e-002   64.1223    20.00000 0.90483
 290.251	    57.15600  1.3585e-002   64.1207    20.00000 0.90449
 290.913	    57.28800  1.3657e-002   64.1201    20.00000 0.90416
 291.577	    57.42000  1.3721e-002   64.1282    20.00000 0.90383
 292.24	    57.55200  1.3791e-002   64.1301    20.00000 0.90349
 292.903	    57.68400  1.3947e-002   64.1462    20.00000 0.90316
 293.565	    57.81600  1.3491e-002   64.1257    20.00000 0.90283
 294.231	    57.94800  1.3107e-002   64.1302    20.00000 0.90250
 294.897	    58.08000  1.2427e-002   64.13    20.00000 0.90216
 295.564	    58.21200  1.2654e-002   64.132    20.00000 0.90183
 296.229	    58.34400  1.2340e-002   64.1406    20.00000 0.90150
 296.893	    58.47600  1.1785e-002   64.1412    20.00000 0.90116
 297.558	    58.60800  1.0589e-002   64.141    20.00000 0.90083
 298.222	    58.74000  1.1017e-002   64.1403    20.00000 0.90050
 298.885	    58.87200  1.1233e-002   64.1384    20.00000 0.90017
 299.548	    59.00400  1.1733e-002   64.1385    20.00000 0.89983
 300.213	    59.13600  1.0844e-002   64.1362    20.00000 0.89950
 300.876	    59.26800  1.0619e-002   64.1404    20.00000 0.89917
 301.539	    59.40000  1.0265e-002   64.1399    20.00000 0.89884
 302.2	    59.53200  1.0222e-002   64.1368    20.00000 0.89851
 302.861	    59.66400  9.8058e-003   64.1366    20.00000 0.89818
 303.522	    59.79600  9.7836e-003   64.1419    20.00000 0.89785
 304.184	    59.92800  9.4753e-003   64.147    20.00000 0.89753
 304.844	    60.06000  9.6204e-003   64.1483    20.00000 0.89720
 305.504	    60.19200  9.6033e-003   64.1447    20.00000 0.89687
 306.162	    60.32400  8.9838e-003   64.1396    20.00000 0.89654
 306.82	    60.45600  9.5920e-003   64.1378    20.00000 0.89621
 307.479	    60.58800  8.3795e-003   64.1403    20.00000 0.89589
 308.142	    60.72000  9.5272e-003   64.1385    20.00000 0.89556
 308.805	    60.85200  8.4689e-003   64.1354    20.00000 0.89524
 309.468	    60.98400  8.6730e-003   64.1345    20.00000 0.89491
 310.129	    61.11600  8.3477e-003   64.1385    20.00000 0.89459
 310.79	    61.24800  8.3599e-003   64.1384    20.00000 0.89426
 311.453	    61.38000  7.5470e-003   64.1417    20.00000 0.89393
 312.118	    61.51200  7.4587e-003   64.1397    20.00000 0.89361
 312.788	    61.64400  6.9753e-003   64.136    20.00000 0.89328
 313.456	    61.77600  7.2973e-003   64.1327    20.00000 0.89296
 314.123	    61.90800  6.5315e-003   64.1264    20.00000 0.89263
 314.787	    62.04000  6.1152e-003   64.1314    20.00000 0.89231
 315.451	    62.17200  7.2039e-003   64.1342    20.00000 0.89198
 316.113	    62.30400  6.5089e-003   64.1344    20.00000 0.89166
 316.773	    62.43600  5.8218e-003   64.1335    20.00000 0.89133
 317.434	    62.56800  5.3801e-003   64.138    20.00000 0.89101
 318.094	    62.70000  4.5669e-003   64.1395    20.00000 0.89069
 318.755	    62.83200  4.3113e-003   64.1377    20.00000 0.89037
 319.415	    62.96400  5.0312e-003   64.1464    20.00000 0.89004
 320.077	    63.09600  4.1344e-003   64.1466    20.00000 0.88972
 320.739	    63.22800  4.1776e-003   64.1512    20.00000 0.88940
 321.402	    63.36000  3.7941e-003   64.1491    20.00000 0.88907
 322.065	    63.49200  3.3845e-003   64.1493    20.00000 0.88875
 322.727	    63.62400  2.3853e-003   64.1495    20.00000 0.88843
 323.388	    63.75600  3.2315e-003   64.1574    20.00000 0.88811
 324.05	    63.88800  2.9660e-003   64.1541    20.00000 0.88779
 324.714	    64.02000  2.5715e-003   64.1515    20.00000 0.88747
 325.377	    64.15200  2.5201e-003   64.1453    20.00000 0.88714
 326.04	    64.28400  2.1524e-003   64.144    20.00000 0.88682
 326.702	    64.41600  1.7901e-003   64.1489    20.00000 0.88650
 327.363	    64.54800  1.8084e-003   64.1544    20.00000 0.88618
 328.024	    64.68000  4.4797e-004   64.1527    20.00000 0.88586
 328.688	    64.81200  1.1845e-003   64.1473    20.00000 0.88553
 329.35	    64.94400  9.3722e-004   64.1494    20.00000 0.88521
 330.012	    65.07600  5.2139e-004   64.1516    20.00000 0.88490
 330.673	    65.20800  6.2049e-005   64.1526    20.00000 0.88458
 331.334	    65.34000 -3.3659e-004   64.1485    20.00000 0.88426
 331.994	    65.47200 -3.3332e-004   64.1519    20.00000 0.88394
 332.656	    65.60400 -1.6112e-004   64.1556    20.00000 0.88362
 333.317	    65.73600  1.1557e-006   64.1582    20.00000 0.88330
 333.977	    65.86800 -5.6497e-004   64.158    20.00000 0.88298
 334.306	    65.93400 -8.8758e-004   64.1573    20.00000 0.88283